Workbook

Sheet readme
A2: url | B2: 該則 Facebook 貼文的原始連結（URL）
A3: user_name | B3: 貼文發文者或粉絲專頁的名稱
A4: title | B4: 貼文的標題（部分分享連結或網誌型貼文才會有，一般純文字貼文，若無標題則空着
A5: text | B5: 貼文的內文完整文字內容
A6: time | B6: 貼文發布的時間
A7: video_url_one | B7: 貼文中所包含的影片連結，若無影片則空着
A8: photo_url_one | B8: 貼文中所包含的圖片連結（第一張），若無圖片則空着
A9: emotion_basic | B9: 貼文 的基本情緒傾向，例如：中性、正面、負面
A10: emotion_detailed | B10: 貼文 更細緻的情緒或語氣分類，例如：開心 / 滿意 / 期待 / 陳述 / 疑問 / 生氣 / 失望 / 驚
A11: theme | B11: 貼文討論的核心主題，例如：收費/價錢 、資訊分享、服務/投訴
A12: info_value | B12: 貼文的目的或價值分類，例如：有行動意向 / 純分享 / 求助 / 廣告
A13: ev_relevance | B13: 貼文與電動車（EV）的相關程度，例如：直接相關、間接相關、完全無關
... A20: sharesCount | B20: 該則貼文被分享的次數

Sheet 香港電動車充電資訊交流 1
A1: url | B1: user_name | C1: time | D1: title | E1: text | F1: video_url_one | G1: photo_url_one | H1: emotion_basic | I1: emotion_detailed | J1: theme | K1: info_value | L1: ev_relevance | M1: Location_Mentioned | N1: EV_Model_Mentioned | O1: Competitor_Brand | P1: Charging_Type | Q1: likesCount | R1: commentsCount | S1: sharesCount
A2: https://www.facebook.com/groups/366950274676457/permalink/1746279596743511/ | B2: RubyOtter8812 | C2: 46159 | E2: 荃灣京匯中心雙雄，經常拍充電位阻住人充電，人哋入嚟充電要比停車費㗎 | G2: https://scontent-sjc6-1.xx.fbcdn.net/v/t39.30808-6/700285578_4361105797501786_7241732557230475897_n.jpg?stp=cp6_dst-jpg_s720x720_tt6&_nc_cat=107&ccb=1-7&_nc_sid=aa7b47&_nc_ohc=1JNTXRdYvB8Q7kNvwFBKp_C&_nc_oc=Ado-o2GDHK2zKnuk4fZYQPQ7H3WqGlq7LZZMZgdN6fRSD0_L5DmXAOTfrdnUF3Pr5-s&_nc_zt=23&_nc_ht=scontent-sjc6-1.xx&_nc_gid=Il4HE2c_YBEaCjFZchdSuA&_nc_ss=72289&oh=00_Af5XMnXTEeg5cdfzHSCtjNLxQC-8s-xyxVJ7tKmDag9VCw&oe=6A10B6E7 | H2: 負面 | I2: 生氣 | J2: 排隊/打尖/霸位 | K2: 純分享 | L2: 直接相關 | M2: 荃灣京匯中心 | N2: null | O2: null | P2: null | Q2: 45 | R2: 28 | S2: 1
A3: https://www.facebook.com/groups/366950274676457/permalink/1746284526743018/ | B3: RubyOtter8812 | C3: 46159 | E3: 入荃灣京匯充電要諗清楚會唔會比油車霸住兩個位，管理處話呢兩部車經常霸住 | G3: https://scontent-sjc3-1.xx.fbcdn.net/v/t39.30808-6/702064419_4361111370834562_7186191070475268686_n.jpg?stp=cp6_dst-jpg_s720x720_tt6&_nc_cat=106&ccb=1-7&_nc_sid=aa7b47&_nc_ohc=zEPnfmkeyuIQ7kNvwGe4dOp&_nc_oc=AdrHaAG36nnXpccvu3QUMbFGqnjcQkoRl7UjPLkLQEeP6VrFIsar9z-VgudAqcIXCIk&_nc_zt=23&_nc_ht=scontent-sjc3-1.xx&_nc_gid=Il4HE2c_YBEaCjFZchdSuA&_nc_ss=72289&oh=00_Af450jqLkHgXj3U1Ub4vAnTIZheZlletniRBeFZq_FYGaA&oe=6A10976D | H3: 負面 | I3: 生氣 | J3: 排隊/打尖/霸位 | K3: 純分享 | L3: 直接相關 | M3: 荃灣京匯中心 | N3: null | O3: null | P3: null | Q3: 0 | R3: 1 | S3: 0
A4: https://www.facebook.com/groups/366950274676457/permalink/1746133363424801/ | B4: Gary Tsui 港車薈轉插 | C4: 46159 | E4: 港車薈PRO X轉插 X 阿維塔07 港車北上充電實況分享 無懼雨天 ，會員直接到珠海港車薈現場測試教學，液冷超充速度滿意！充電速度達到268KW，30%電量半小時充滿！ 越級顏值 悅目亦悅心 港車薈PRO X 讓你充電無憂！ 港車北上全方位服務 - 港車薈 #港車北上 #快充轉插 | H4: 正面 | I4: 滿意 | J4: 廣告/促銷 | K4: 廣告 | L4: 直接相關 | M4: null | N4: 阿維塔07 | O4: null | P4: 液冷超充,268kW | Q4: 0 | R4: 0 | S4: 0
A5: https://www.facebook.com/groups/366950274676457/permalink/1741215493916588/ | B5: Rex Lam | C5: 46153 | E5: 多點方便系統優越 | G5: https://scontent-atl3-2.xx.fbcdn.net/v/t39.30808-6/695032015_10242884265788812_5596688430513272657_n.jpg?stp=dst-jpg_s720x720_tt6&_nc_cat=104&ccb=1-7&_nc_sid=aa7b47&_nc_ohc=4Y_RXxuM76cQ7kNvwEY-eJ5&_nc_oc=AdpsQLr3zlzbLMjL8zLYGH0cn1q7zSn7wBm6alEcst5Z6yEGeG1-NRJaJ79NuUw_9Gs&_nc_zt=23&_nc_ht=scontent-atl3-2.xx&_nc_gid=edX6JYlN3__cukAu7Y3kBw&_nc_ss=7c289&oh=00_Af7TTRMpPMmNuIZn1zFJf5wFhe37VJCH8tfHgBrPwPqaZQ&oe=6A10C255 | H5: 正面 | I5: 滿意 | J5: 廣告/促銷 | K5: 廣告 | L5: 直接相關 | M5: null | N5: null | O5: null | P5: null | Q5: 2 | R5: 0 | S5: 0
A6: https://www.facebook.com/groups/366950274676457/permalink/1740287304009407/ | B6: 翡翠家 | C6: 46152 | E6: 承接 派傳單 貼海報 貼街招 掛橫額 掛banner 工商廈派傳單 印傳單 印街招 想宣傳又想慳荷包 平價宣傳 增加生意額 增加公司知名度 全港 貼海報 海報宣傳 印傳單 印海報 印街招 派傳單 街上派傳單 派發傳單 工商廈派傳單 商廈派傳單 工廈派傳單 屋苑入傳單 屋苑派傳單 屋苑入信箱 私樓派傳單 私樓入傳單 私樓入信箱 街頭派傳單 工商廈入傳單 工廈入傳單 商廈入傳單 派贈品 派sample 放易拉架 貼海報 貼街招 公屋派傳單 派通函 入通函 掛banner 放banner 合適行業 餐廳 補習社 茶飲 工程公司 太陽能公司 二餸飯 零售 美容儀器 裝修工程 防水工程 鋁窗工程 地產代理 保險代理 產品宣傳 品牌宣傳 電腦維修 食堂宣傳 宣傳易派傳單公司 WhatsApp: 94518014 https://api.whatsapp.com/send?phone=85294518014 承接全港各區派傳單.貼海報街招服務 我們的網站 https://myeasypromotion.com/ 我們的客戶 https://myeasypromotion.com/%e6%88%91%e5%80%91%e7%9a%84%e5%ae%a2%e6%88%b6/ 印傳單 https://myeasypromotion.com/%E5%8D%B0%E5%88%B7%E6%9C%8D%E5%8B%99/ Facebook 專頁 https://www.facebook.com/share/19Vz17DbxX/ 旋轉拍賣商店 https://carousell.app.link/me5wd2PN5Vb 海報宣傳 •••••••••••••••• 街上貼街招/貼海報 海報宣傳 全港各區, 每區300張起接, 提供影相為證服務. ⭕A4每區 300張起（每張$1.8） ⭕A5每區300張起(每張$1.2） ⭕A6每區300張起（每張$ 1) ⭕每張:A3/5 $ ; A2 /5.5 $ ; A1/ 6.5$ 每區 300張 貼村屋範圍街招海報 海報會全部拍攝相片 街招拍攝35張相片 . •••••••••••••••••• 洗樓入公屋 (上樓派傳單) 每張 0.65 1000張起 會拍攝150張相片 工商廈洗樓 舊式工商廈 會拍攝 35張相片證明 150元3座 130元 5座 120元 10座 110元20座 95元 30座 ⭕入村屋地下信箱 ：$270起接單 每區最少300戶起x9毫子 ⭕入唐樓地下信箱：$180 起接單 每區最少300戶起.x6毫子 汽車派傳單 派名片 的士或call 車平台公司或汽車美容公司 優惠 1.5 1張 放置 banner 掛banner 街頭放bannet 已申請地政署獲批放置 包取貨 10條以下 120元條 20條起 100元1條 要有放資詳細資料 code 會影相證明 偏遠地或 加 30元 1條 街上(舉牌)派傳單服務： 派傳單 2小時起 85元1小時 派傳單 3小時 80元 1小時 派傳單 4小時起 80元1小時 舉牌放傳單 加 10元1小時 加易拉架 加25元1小時 著制服 加 20元1小時 半山學校 加80元 1小時 派贈品 派飲品 派試用裝 派香水 派樣本 派sample 派公屋信箱 已申請入信箱 200戶 70元 每座 元 500戶 125元 750戶 188元 1000戶 250元. 最小 5 座起 已成功申請入公屋通函 誠意合作：WhatsApp: 94518014 派傳單，貼海報，貼街招 洗樓派傳單. 工廈商廈洗樓和私人屋苑,村屋，唐樓等入信箱服務. 印傳單 光粉紙 115克 210*285mm 2000張 需帶稿件 包本地送貨 460元 A4 尺寸 2000張 430元 A4 尺寸 4000張 660元 其後每 1000張 100元 A5 2000張 330元 A5 4000張 530元 其後每 1000張 100元 A6 2000張 300元 其後 每1000張80元 包送貨 印刷 A3. 海報 300張起 2.4元張 印刷 A2 海報 600張起 3元張 印刷 A1 海報 128克紙 600張起 3.4元 張 印刷 A1 海報 115克紙 700張 3元 #派傳單 #傳單員 #派傳單公司 #傳單印刷 #推廣員 #Promoter #印傳單 #派報公司 #投遞信箱 #發傳單 #發名片 #唐樓派傳單 #公屋派傳單 #貼海報 #貼街招 #貼貼紙 #全港專業洗樓派傳單 #派樓及印刷服務 #派傳單服務 #洗樓 #市場推廣 #宣傳 #派傳單服務 #海報宣傳 #派傳單 #推廣 #宣傳 #廣告 #Promotion #村屋派傳單 #車輛派傳單 #汽車派傳單 #村屋派信箱 #唐樓派信箱 #舊樓派傳單 #舊樓派信箱 # 工商廈派傳單 | F6: https://video-atl3-1.xx.fbcdn.net/o1/v/t2/f2/m366/AQMJ0hai10LJrYAmXaNgZxhI-uGdO9ELUW3-8FSzlNZPDym3IiEOsjMnb5XCbONCOdGjpquDRGSNGhniVrmdx1x7XxGQZJNP0zNB_rn1qBvrrw.mp4?_nc_cat=103&_nc_sid=5e9851&_nc_ht=video-atl3-1.xx.fbcdn.net&_nc_ohc=mQoetQy1Aw8Q7kNvwGgzQSs&efg=eyJ2ZW5jb2RlX3RhZyI6Inhwdl9wcm9ncmVzc2l2ZS5GQUNFQk9PSy4uQzMuMTA4OC5kYXNoX2gyNjQtYmFzaWMtZ2VuMl83MjBwIiwieHB2X2Fzc2V0X2lkIjo5Njk0ODQ0OTkwMDUyNzMsImFzc2V0X2FnZV9kYXlzIjo4LCJ2aV91c2VjYXNlX2lkIjoxMDEyMSwiZHVyYXRpb25fcyI6MTY0LCJ1cmxnZW5fc291cmNlIjoid3d3In0%3D&ccb=17-1&vs=7c17d4b9da931767&_nc_vs=HBksFQIYRWZiX2VwaGVtZXJhbC9GODQ0RUE2QjE4NkJBMzk4N0U5QjIyREUxMzk3RTBBMF9tdF8xX3ZpZGVvX2Rhc2hpbml0Lm1wNBUAAsgBEgAVAhhAZmJfcGVybWFuZW50L0Y5NEEwNUQ2RjZENzc1ODdGMjQxQzEwMkU5Qzc5REExX2F1ZGlvX2Rhc2hpbml0Lm1wNBUCAsgBEgAoABgAGwKIB3VzZV9vaWwBMRJwcm9ncmVzc2l2ZV9yZWNpcGUBMRUAACayve2ytu-4AxUCKAJDMywXQGSQo9cKPXEYGWRhc2hfaDI2NC1iYXNpYy1nZW4yXzcyMHARAHUCZZKeAQA&_nc_gid=edX6JYlN3__cukAu7Y3kBw&_nc_ss=7c289&_nc_zt=28&oh=00_Af5LnEZVP7vNRknLenbr_HgNli82ynpZASYKQJEFlZ0Dog&oe=6A109999&bitrate=184413&tag=dash_h264-basic-gen2_720p | H6: 中性 | I6: 陳述 | J6: 廣告/促銷 | K6: 廣告 | L6: 無關 | M6: null | N6: null | O6: null | P6: null | Q6: 0 | R6: 0 | S6: 0
A7: https://www.facebook.com/groups/366950274676457/permalink/1738832300821574/ | B7: 翡翠家 | C7: 46150 | E7: 承接 派傳單 貼海報 貼街招 掛橫額 掛banner 工商廈派傳單 印傳單 印街招 想宣傳又想慳荷包 平價宣傳 增加生意額 增加公司知名度 全港 貼海報 海報宣傳 印傳單 印海報 印街招 派傳單 街上派傳單 派發傳單 工商廈派傳單 商廈派傳單 工廈派傳單 屋苑入傳單 屋苑派傳單 屋苑入信箱 私樓派傳單 私樓入傳單 私樓入信箱 街頭派傳單 工商廈入傳單 工廈入傳單 商廈入傳單 派贈品 派sample 放易拉架 貼海報 貼街招 公屋派傳單 派通函 入通函 掛banner 放banner 合適行業 餐廳 補習社 茶飲 工程公司 太陽能公司 二餸飯 零售 美容儀器 裝修工程 防水工程 鋁窗工程 地產代理 保險代理 產品宣傳 品牌宣傳 電腦維修 食堂宣傳 宣傳易派傳單公司 WhatsApp: 94518014 https://api.whatsapp.com/send?phone=85294518014 承接全港各區派傳單.貼海報街招服務 我們的網站 https://myeasypromotion.com/ 我們的客戶 https://myeasypromotion.com/%e6%88%91%e5%80%91%e7%9a%84%e5%ae%a2%e6%88%b6/ 印傳單 https://myeasypromotion.com/%E5%8D%B0%E5%88%B7%E6%9C%8D%E5%8B%99/ Facebook 專頁 https://www.facebook.com/share/19Vz17DbxX/ 旋轉拍賣商店 https://carousell.app.link/me5wd2PN5Vb 海報宣傳 •••••••••••••••• 街上貼街招/貼海報 海報宣傳 全港各區, 每區300張起接, 提供影相為證服務. ⭕A4每區 300張起（每張$1.8） ⭕A5每區300張起(每張$1.2） ⭕A6每區300張起（每張$ 1) ⭕每張:A3/5 $ ; A2 /5.5 $ ; A1/ 6.5$ 每區 300張 貼村屋範圍街招海報 海報會全部拍攝相片 街招拍攝35張相片 . •••••••••••••••••• 洗樓入公屋 (上樓派傳單) 每張 0.65 1000張起 會拍攝150張相片 工商廈洗樓 舊式工商廈 會拍攝 35張相片證明 150元3座 130元 5座 120元 10座 110元20座 95元 30座 ⭕入村屋地下信箱 ：$270起接單 每區最少300戶起x9毫子 ⭕入唐樓地下信箱：$180 起接單 每區最少300戶起.x6毫子 汽車派傳單 派名片 的士或call 車平台公司或汽車美容公司 優惠 1.5 1張 放置 banner 掛banner 街頭放bannet 已申請地政署獲批放置 包取貨 10條以下 120元條 20條起 100元1條 要有放資詳細資料 code 會影相證明 偏遠地或 加 30元 1條 街上(舉牌)派傳單服務： 派傳單 2小時起 85元1小時 派傳單 3小時 80元 1小時 派傳單 4小時起 80元1小時 舉牌放傳單 加 10元1小時 加易拉架 加25元1小時 著制服 加 20元1小時 半山學校 加80元 1小時 派贈品 派飲品 派試用裝 派香水 派樣本 派sample 派公屋信箱 已申請入信箱 200戶 70元 每座 元 500戶 125元 750戶 188元 1000戶 250元. 最小 5 座起 已成功申請入公屋通函 誠意合作：WhatsApp: 94518014 派傳單，貼海報，貼街招 洗樓派傳單. 工廈商廈洗樓和私人屋苑,村屋，唐樓等入信箱服務. 印傳單 光粉紙 115克 210*285mm 2000張 需帶稿件 包本地送貨 460元 A4 尺寸 2000張 430元 A4 尺寸 4000張 660元 其後每 1000張 100元 A5 2000張 330元 A5 4000張 530元 其後每 1000張 100元 A6 2000張 300元 其後 每1000張80元 包送貨 印刷 A3. 海報 300張起 2.4元張 印刷 A2 海報 600張起 3元張 印刷 A1 海報 128克紙 600張起 3.4元 張 印刷 A1 海報 115克紙 700張 3元 #派傳單 #傳單員 #派傳單公司 #傳單印刷 #推廣員 #Promoter #印傳單 #派報公司 #投遞信箱 #發傳單 #發名片 #唐樓派傳單 #公屋派傳單 #貼海報 #貼街招 #貼貼紙 #全港專業洗樓派傳單 #派樓及印刷服務 #派傳單服務 #洗樓 #市場推廣 #宣傳 #派傳單服務 #海報宣傳 #派傳單 #推廣 #宣傳 #廣告 #Promotion #村屋派傳單 #車輛派傳單 #汽車派傳單 #村屋派信箱 #唐樓派信箱 #舊樓派傳單 #舊樓派信箱 # 工商廈派傳單 | F7: https://video-lga3-3.xx.fbcdn.net/o1/v/t2/f2/m366/AQOBSy4LumdSIuzk7S77hKz7jMfZ-PWOCmW81Iix0BhJYS0if6AGBCXlilSbXuuKmvX8tQqHsOfuZsoilCot9xxdcGCOGhrPFCfkeya8YmLnCg.mp4?_nc_cat=106&_nc_sid=5e9851&_nc_ht=video-lga3-3.xx.fbcdn.net&_nc_ohc=e__eJPlzw60Q7kNvwEC2fGp&efg=eyJ2ZW5jb2RlX3RhZyI6Inhwdl9wcm9ncmVzc2l2ZS5GQUNFQk9PSy4uQzMuMTA4OC5kYXNoX2gyNjQtYmFzaWMtZ2VuMl83MjBwIiwieHB2X2Fzc2V0X2lkIjo4MTIyOTg4OTQ5NjQzMDMsImFzc2V0X2FnZV9kYXlzIjo5LCJ2aV91c2VjYXNlX2lkIjoxMDEyMSwiZHVyYXRpb25fcyI6MTY0LCJ1cmxnZW5fc291cmNlIjoid3d3In0%3D&ccb=17-1&vs=157a8875f6384c0d&_nc_vs=HBksFQIYRWZiX2VwaGVtZXJhbC9GRDRBQzU4MjY1RDZFNDczRUJFNDdDOEEyRDU4ODNCMl9tdF8xX3ZpZGVvX2Rhc2hpbml0Lm1wNBUAAsgBEgAVAhhAZmJfcGVybWFuZW50LzEwNEMwMDkxQzQ2RjFCMENFRTNCNUYwMDc2MEYyRkFFX2F1ZGlvX2Rhc2hpbml0Lm1wNBUCAsgBEgAoABgAGwKIB3VzZV9vaWwBMRJwcm9ncmVzc2l2ZV9yZWNpcGUBMRUAACae2a-xgrLxAhUCKAJDMywXQGSQo9cKPXEYGWRhc2hfaDI2NC1iYXNpYy1nZW4yXzcyMHARAHUCZZKeAQA&_nc_gid=WCZZ1cfkRQjguD8a8YMU5Q&_nc_ss=72289&_nc_zt=28&oh=00_Af5j9SCzuY7jam_E-uc8MgnBOJnLPSVPUvMP6Z3b89O0OA&oe=6A10B532&bitrate=184413&tag=dash_h264-basic-gen2_720p | H7: 中性 | I7: 陳述 | J7: 其他 | K7: 廣告 | L7: 無關 | M7: null | N7: null | O7: null | P7: null | Q7: 0 | R7: 0 | S7: 0
A8: https://www.facebook.com/groups/366950274676457/permalink/1738538877517583/ | B8: Gary Tsui 港車薈轉插 | C8: 46150 | E8: 港車薈PRO X 轉插 X 現代IONIQ 5 珠海山姆#八達通液冷超充站 實況分享。 越級顏值 悅目亦悅心 港車薈PRO X 讓你充電無憂！ 選擇最優品牌，質量，售後，服務都是NO.1 #港車薈 #DC快充轉插 #CCS2 #GBT #電車北上 | H8: 正面 | I8: 滿意 | J8: 廣告/促銷 | K8: 廣告 | L8: 直接相關 | M8: 珠海山姆 | N8: 現代IONIQ 5 | O8: 港車薈 | P8: DC快充、超充、CCS2、GBT | Q8: 0 | R8: 0 | S8: 0
A9: https://www.facebook.com/groups/366950274676457/permalink/1738448004193337/ | B9: Simon Lee | C9: 46150 | E9: 大角咀 One Bedford Place 停車場， 終於有TESLA免費EV充電 | H9: 正面 | I9: 開心 | J9: 充電站設施/位置 | K9: 純分享 | L9: 直接相關 | M9: 大角咀 One Bedford Place | N9: null | O9: Tesla | P9: null | Q9: 2 | R9: 0 | S9: 0
A10: https://www.facebook.com/groups/366950274676457/permalink/1738332220871582/ | B10: Jack Chan | C10: 46149 | E10: 月租停車場終於減價 幫補吓保養、牌費都好 佐敦高臨停車場做月租優惠！(電動車) | H10: 正面 | I10: 滿意 | J10: 收費/價錢 | K10: 純分享 | L10: 間接相關 | M10: 佐敦高臨停車場 | N10: null | O10: null | P10: null | Q10: 16 | R10: 1 | S10: 0
A11: https://www.facebook.com/groups/366950274676457/permalink/1737987944239343/ | B11: 翡翠家 | C11: 46149 | E11: 承接 派傳單 貼海報 貼街招 掛橫額 掛banner 工商廈派傳單 印傳單 印街招 想宣傳又想慳荷包 平價宣傳 增加生意額 增加公司知名度 全港 貼海報 海報宣傳 印傳單 印海報 印街招 派傳單 街上派傳單 派發傳單 工商廈派傳單 商廈派傳單 工廈派傳單 屋苑入傳單 屋苑派傳單 屋苑入信箱 私樓派傳單 私樓入傳單 私樓入信箱 街頭派傳單 工商廈入傳單 工廈入傳單 商廈入傳單 派贈品 派sample 放易拉架 貼海報 貼街招 公屋派傳單 派通函 入通函 掛banner 放banner 合適行業 餐廳 補習社 茶飲 工程公司 太陽能公司 二餸飯 零售 美容儀器 裝修工程 防水工程 鋁窗工程 地產代理 保險代理 產品宣傳 品牌宣傳 電腦維修 食堂宣傳 宣傳易派傳單公司 WhatsApp: 94518014 https://api.whatsapp.com/send?phone=85294518014 承接全港各區派傳單.貼海報街招服務 我們的網站 https://myeasypromotion.com/ 我們的客戶 https://myeasypromotion.com/%e6%88%91%e5%80%91%e7%9a%84%e5%ae%a2%e6%88%b6/ 印傳單 https://myeasypromotion.com/%E5%8D%B0%E5%88%B7%E6%9C%8D%E5%8B%99/ Facebook 專頁 https://www.facebook.com/share/19Vz17DbxX/ 旋轉拍賣商店 https://carousell.app.link/me5wd2PN5Vb 海報宣傳 •••••••••••••••• 街上貼街招/貼海報 海報宣傳 全港各區, 每區300張起接, 提供影相為證服務. ⭕A4每區 300張起（每張$1.8） ⭕A5每區300張起(每張$1.2） ⭕A6每區300張起（每張$ 1) ⭕每張:A3/5 $ ; A2 /5.5 $ ; A1/ 6.5$ 每區 300張 貼村屋範圍街招海報 海報會全部拍攝相片 街招拍攝35張相片 . •••••••••••••••••• 洗樓入公屋 (上樓派傳單) 每張 0.65 1000張起 會拍攝150張相片 工商廈洗樓 舊式工商廈 會拍攝 35張相片證明 150元3座 130元 5座 120元 10座 110元20座 95元 30座 ⭕入村屋地下信箱 ：$270起接單 每區最少300戶起x9毫子 ⭕入唐樓地下信箱：$180 起接單 每區最少300戶起.x6毫子 汽車派傳單 派名片 的士或call 車平台公司或汽車美容公司 優惠 1.5 1張 放置 banner 掛banner 街頭放bannet 已申請地政署獲批放置 包取貨 10條以下 120元條 20條起 100元1條 要有放資詳細資料 code 會影相證明 偏遠地或 加 30元 1條 街上(舉牌)派傳單服務： 派傳單 2小時起 85元1小時 派傳單 3小時 80元 1小時 派傳單 4小時起 80元1小時 舉牌放傳單 加 10元1小時 加易拉架 加25元1小時 著制服 加 20元1小時 半山學校 加80元 1小時 派贈品 派飲品 派試用裝 派香水 派樣本 派sample 派公屋信箱 已申請入信箱 200戶 70元 每座 元 500戶 125元 750戶 188元 1000戶 250元. 最小 5 座起 已成功申請入公屋通函 誠意合作：WhatsApp: 94518014 派傳單，貼海報，貼街招 洗樓派傳單. 工廈商廈洗樓和私人屋苑,村屋，唐樓等入信箱服務. 印傳單 光粉紙 115克 210*285mm 2000張 需帶稿件 包本地送貨 460元 A4 尺寸 2000張 430元 A4 尺寸 4000張 660元 其後每 1000張 100元 A5 2000張 330元 A5 4000張 530元 其後每 1000張 100元 A6 2000張 300元 其後 每1000張80元 包送貨 印刷 A3. 海報 300張起 2.4元張 印刷 A2 海報 600張起 3元張 印刷 A1 海報 128克紙 600張起 3.4元 張 印刷 A1 海報 115克紙 700張 3元 #派傳單 #傳單員 #派傳單公司 #傳單印刷 #推廣員 #Promoter #印傳單 #派報公司 #投遞信箱 #發傳單 #發名片 #唐樓派傳單 #公屋派傳單 #貼海報 #貼街招 #貼貼紙 #全港專業洗樓派傳單 #派樓及印刷服務 #派傳單服務 #洗樓 #市場推廣 #宣傳 #派傳單服務 #海報宣傳 #派傳單 #推廣 #宣傳 #廣告 #Promotion #村屋派傳單 #車輛派傳單 #汽車派傳單 #村屋派信箱 #唐樓派信箱 #舊樓派傳單 #舊樓派信箱 # 工商廈派傳單 | F11: https://video-ord5-2.xx.fbcdn.net/o1/v/t2/f2/m366/AQO68B5K_trnqYX5MX0ve6hinrM5mfw3ijgJ0VZAIeurJFaHKgVmLVtCk__sP4JIUC1XrrAAKEFCRFSMQrKzl57AhCm5lfcgt46z2IBBC03yfw.mp4?_nc_cat=103&_nc_sid=5e9851&_nc_ht=video-ord5-2.xx.fbcdn.net&_nc_ohc=el9pftu8RG8Q7kNvwHTDBNS&efg=eyJ2ZW5jb2RlX3RhZyI6Inhwdl9wcm9ncmVzc2l2ZS5GQUNFQk9PSy4uQzMuMTA4OC5kYXNoX2gyNjQtYmFzaWMtZ2VuMl83MjBwIiwieHB2X2Fzc2V0X2lkIjoxNTQwODYwODUxMDA2NzIxLCJhc3NldF9hZ2VfZGF5cyI6MTAsInZpX3VzZWNhc2VfaWQiOjEwMTIxLCJkdXJhdGlvbl9zIjoxNjQsInVybGdlbl9zb3VyY2UiOiJ3d3cifQ%3D%3D&ccb=17-1&vs=456289e30dd5702d&_nc_vs=HBksFQIYRWZiX2VwaGVtZXJhbC8xMTQyN0NEQ0UxQUU0QTAzQUUwOTE2MUMyRURCMzlBRl9tdF8xX3ZpZGVvX2Rhc2hpbml0Lm1wNBUAAsgBEgAVAhhAZmJfcGVybWFuZW50LzVGNEUyMjU1OEE2OTdGOTFDQTQxMEFFOUNERjVBMkEwX2F1ZGlvX2Rhc2hpbml0Lm1wNBUCAsgBEgAoABgAGwKIB3VzZV9vaWwBMRJwcm9ncmVzc2l2ZV9yZWNpcGUBMRUAACaCtOH689m8BRUCKAJDMywXQGSQo9cKPXEYGWRhc2hfaDI2NC1iYXNpYy1nZW4yXzcyMHARAHUCZZKeAQA&_nc_gid=ytKkpwsqmUAL7DgRjBRMIw&_nc_ss=72289&_nc_zt=28&oh=00_Af6hQtEjN5mkfdllPGOs-0yihp-RNzjl27iT8hcr7vckyg&oe=6A109A1D&bitrate=184413&tag=dash_h264-basic-gen2_720p | H11: 中性 | I11: 陳述 | J11: 廣告/促銷 | K11: 廣告 | L11: 無關 | M11: null | N11: null | O11: null | P11: null | Q11: 0 | R11: 0 | S11: 0
A12: https://www.facebook.com/groups/366950274676457/permalink/1737587170946087/ | B12: Amuro Lee | C12: 46148 | E12: 1. 本田（Honda）於 2026 年 4 月 16 日正式在日本開啟全新純電車仔 Super-ONE （歐美稱為 Super-N）的預購活動，並預定於 5 月下旬正式上市。儘管官方尚未揭曉最終建議售價，但這款強調「純粹駕馭樂趣」的車款已在當地掀起搶購熱潮。根據日本經銷商的最新消息，Super-ONE 的預接訂單量遠超預期，目前的交車等候期已拉長至 5 到 6 個月，足見這款結合復古與運動性能車仔魅力驚人。#拍車新聞網 2. Super-ONE 的設計靈感源自 2024 年 Goodwood 速度嘉年華亮相的 Super EV Concept，並以此為基礎進行量產化。為了強化運動氣息，Super-ONE 採用了顯著外擴的輪拱與寬體設計，車寬來到 1,595mm，車長則延伸至 3,595mm，這意味著它已超越了日本傳統 K-Car（輕自動車）的尺碼限制，正式跨入乘用車（小型車）類別。外觀細節上，重新塑形的前泵把加入了直立式導流口，搭配專屬的紫色車身塗裝（可選黑色車頂）、15 吋啞光黑多輻式空力輪圈與車尾擾流尾翼，營造出宛如 80 年代 City Turbo II 再世的鋼砲神韻。 3. 動力表現更是 Super-ONE 的精髓所在，其研發目標是打破電動車枯燥乏味的既定印象。雖然採單馬達前驅配置，但在一般模式下具備 64 匹馬力，一旦按下方向盤上的「BOOST」模式按鈕，最大輸出將瞬間提升至 95 匹（70kW） 之譜。配合僅 1,090 公斤 的輕量化車身，Super-ONE 具備極為靈活且強勁的加速反應。為了提升感官沉浸感，本田更為其配置了主動式聲浪控制系統與模擬換檔功能，透過標配的 BOSE 高級音響系統 傳遞合成的引擎轟鳴聲，甚至在換檔點提供細微的震動回饋。 4. 座艙空間同樣展現「以駕駛為中心」的初衷，換裝了專屬運動化座椅，以類麂皮材質包覆提供極佳防滑效果。內裝配置包含 7 吋數位儀表與 9 吋中控螢幕，在 BOOST 模式下儀表會切換為專屬圖型顯示。而在實用性方面，受惠於薄型低重心電池布局，車輛具備 274 公里（WLTC 模式） 的續航里程，並支援 50kW 快充與 AC1500W 外部供電功能（V2L），兼顧了日常通勤便利與週末跑山樂趣。 | G12: https://scontent.fhkg10-2.fna.fbcdn.net/v/t39.30808-6/690650422_1413969480745884_1036797877813894995_n.jpg?stp=dst-jpg_p526x296_tt6&_nc_cat=108&ccb=1-7&_nc_sid=127cfc&_nc_ohc=Ijfwew97gxcQ7kNvwHTHbVQ&_nc_oc=AdozeuuiiipM4cUnBd3Wg80IXi2fU7Et-MbxL5L14lOKHLTGcrlE2EyGFBDT1OFa41g&_nc_zt=23&_nc_ht=scontent.fhkg10-2.fna&_nc_gid=hhm3hxkX8mxEimLjr45G8A&_nc_ss=7b2a8&oh=00_Af4wky3M62s95jwfhyvfQTxOKEepNNdsHHd7kzFUMVY88A&oe=6A12DDE7 | H12: 中性 | I12: 陳述 | J12: 安裝/硬件/技術 | K12: 純分享 | L12: 直接相關 | M12: 日本 | N12: Honda Super-ONE | O12: null | P12: 50kW 快充 | Q12: 1 | R12: 0 | S12: 0
A13: https://www.facebook.com/groups/366950274676457/permalink/1737096300995174/ | B13: 翡翠家 | C13: 46148 | E13: 承接 派傳單 貼海報 貼街招 掛橫額 掛banner 工商廈派傳單 印傳單 印街招 想宣傳又想慳荷包 平價宣傳 增加生意額 增加公司知名度 全港 貼海報 海報宣傳 印傳單 印海報 印街招 派傳單 街上派傳單 派發傳單 工商廈派傳單 商廈派傳單 工廈派傳單 屋苑入傳單 屋苑派傳單 屋苑入信箱 私樓派傳單 私樓入傳單 私樓入信箱 街頭派傳單 工商廈入傳單 工廈入傳單 商廈入傳單 派贈品 派sample 放易拉架 貼海報 貼街招 公屋派傳單 派通函 入通函 掛banner 放banner 合適行業 餐廳 補習社 茶飲 工程公司 太陽能公司 二餸飯 零售 美容儀器 裝修工程 防水工程 鋁窗工程 地產代理 保險代理 產品宣傳 品牌宣傳 電腦維修 食堂宣傳 宣傳易派傳單公司 WhatsApp: 94518014 https://api.whatsapp.com/send?phone=85294518014 承接全港各區派傳單.貼海報街招服務 我們的網站 https://myeasypromotion.com/ 我們的客戶 https://myeasypromotion.com/%e6%88%91%e5%80%91%e7%9a%84%e5%ae%a2%e6%88%b6/ 印傳單 https://myeasypromotion.com/%E5%8D%B0%E5%88%B7%E6%9C%8D%E5%8B%99/ Facebook 專頁 https://www.facebook.com/share/19Vz17DbxX/ 旋轉拍賣商店 https://carousell.app.link/me5wd2PN5Vb 海報宣傳 •••••••••••••••• 街上貼街招/貼海報 海報宣傳 全港各區, 每區300張起接, 提供影相為證服務. ⭕A4每區 300張起（每張$1.8） ⭕A5每區300張起(每張$1.2） ⭕A6每區300張起（每張$ 1) ⭕每張:A3/5 $ ; A2 /5.5 $ ; A1/ 6.5$ 每區 300張 貼村屋範圍街招海報 海報會全部拍攝相片 街招拍攝35張相片 . •••••••••••••••••• 洗樓入公屋 (上樓派傳單) 每張 0.65 1000張起 會拍攝150張相片 工商廈洗樓 舊式工商廈 會拍攝 35張相片證明 150元3座 130元 5座 120元 10座 110元20座 95元 30座 ⭕入村屋地下信箱 ：$270起接單 每區最少300戶起x9毫子 ⭕入唐樓地下信箱：$180 起接單 每區最少300戶起.x6毫子 汽車派傳單 派名片 的士或call 車平台公司或汽車美容公司 優惠 1.5 1張 放置 banner 掛banner 街頭放bannet 已申請地政署獲批放置 包取貨 10條以下 120元條 20條起 100元1條 要有放資詳細資料 code 會影相證明 偏遠地或 加 30元 1條 街上(舉牌)派傳單服務： 派傳單 2小時起 85元1小時 派傳單 3小時 80元 1小時 派傳單 4小時起 80元1小時 舉牌放傳單 加 10元1小時 加易拉架 加25元1小時 著制服 加 20元1小時 半山學校 加80元 1小時 派贈品 派飲品 派試用裝 派香水 派樣本 派sample 派公屋信箱 已申請入信箱 200戶 70元 每座 元 500戶 125元 750戶 188元 1000戶 250元. 最小 5 座起 已成功申請入公屋通函 誠意合作：WhatsApp: 94518014 派傳單，貼海報，貼街招 洗樓派傳單. 工廈商廈洗樓和私人屋苑,村屋，唐樓等入信箱服務. 印傳單 光粉紙 115克 210*285mm 2000張 需帶稿件 包本地送貨 460元 A4 尺寸 2000張 430元 A4 尺寸 4000張 660元 其後每 1000張 100元 A5 2000張 330元 A5 4000張 530元 其後每 1000張 100元 A6 2000張 300元 其後 每1000張80元 包送貨 印刷 A3. 海報 300張起 2.4元張 印刷 A2 海報 600張起 3元張 印刷 A1 海報 128克紙 600張起 3.4元 張 印刷 A1 海報 115克紙 700張 3元 #派傳單 #傳單員 #派傳單公司 #傳單印刷 #推廣員 #Promoter #印傳單 #派報公司 #投遞信箱 #發傳單 #發名片 #唐樓派傳單 #公屋派傳單 #貼海報 #貼街招 #貼貼紙 #全港專業洗樓派傳單 #派樓及印刷服務 #派傳單服務 #洗樓 #市場推廣 #宣傳 #派傳單服務 #海報宣傳 #派傳單 #推廣 #宣傳 #廣告 #Promotion #村屋派傳單 #車輛派傳單 #汽車派傳單 #村屋派信箱 #唐樓派信箱 #舊樓派傳單 #舊樓派信箱 # 工商廈派傳單 | F13: https://video.fagc3-2.fna.fbcdn.net/o1/v/t2/f2/m366/AQMr6smpiZg7OyGnCCy053TgiBlHOxtWY_lOS7uTJoofepUtkAqc75bUBFIulQTHRAzAk9kO6Yq5voWVXtrjJtmsQ6R5KnQXhxs_U0O6RhaNAw.mp4?_nc_cat=105&_nc_oc=AdrDpK6xnqPeyzfYGSF9W1s8qHLZw6zjRUomj11T3zeo_28RwGDl86i6BjrXB9ZGhQE&_nc_sid=5e9851&_nc_ht=video.fagc3-2.fna.fbcdn.net&_nc_ohc=JkbZJQRs-kMQ7kNvwHcTDzj&efg=eyJ2ZW5jb2RlX3RhZyI6Inhwdl9wcm9ncmVzc2l2ZS5GQUNFQk9PSy4uQzMuMTA4OC5kYXNoX2gyNjQtYmFzaWMtZ2VuMl83MjBwIiwieHB2X2Fzc2V0X2lkIjo5OTE3NzI2ODA0NTU4NzEsImFzc2V0X2FnZV9kYXlzIjoxMiwidmlfdXNlY2FzZV9pZCI6MTAxMjEsImR1cmF0aW9uX3MiOjE2NCwidXJsZ2VuX3NvdXJjZSI6Ind3dyJ9&ccb=17-1&vs=29abefa3b26a59a2&_nc_vs=HBksFQIYRWZiX2VwaGVtZXJhbC85NzQ0REVCMEMxOEJDNjM4OEU3MzM1MDQ5MTk4OEY5MV9tdF8xX3ZpZGVvX2Rhc2hpbml0Lm1wNBUAAsgBEgAVAhhAZmJfcGVybWFuZW50LzhDNDU1QjNBNjNBRUU0N0VBOEYzRTY0ODI0RDA4NjlEX2F1ZGlvX2Rhc2hpbml0Lm1wNBUCAsgBEgAoABgAGwKIB3VzZV9vaWwBMRJwcm9ncmVzc2l2ZV9yZWNpcGUBMRUAACb-moil4oDDAxUCKAJDMywXQGSQo9cKPXEYGWRhc2hfaDI2NC1iYXNpYy1nZW4yXzcyMHARAHUCZZKeAQA&_nc_gid=lalNyvLnisdorAjl4SJoBA&_nc_ss=72289&_nc_zt=28&oh=00_Af4PbcL39FSu-pQtQi43QV9LRD9K68K_2nwf8HtfZH_kWA&oe=6A10B97B&bitrate=184413&tag=dash_h264-basic-gen2_720p | H13: 中性 | I13: 陳述 | J13: 廣告/促銷 | K13: 廣告 | L13: 無關 | M13: null | N13: null | O13: null | P13: null | Q13: 0 | R13: 0 | S13: 0
A14: https://www.facebook.com/groups/366950274676457/permalink/1734463431258461/ | B14: 翡翠家 | C14: 46145 | E14: 承接 派傳單 貼海報 貼街招 掛橫額 掛banner 工商廈派傳單 印傳單 印街招 想宣傳又想慳荷包 平價宣傳 增加生意額 增加公司知名度 全港 貼海報 海報宣傳 印傳單 印海報 印街招 派傳單 街上派傳單 派發傳單 工商廈派傳單 商廈派傳單 工廈派傳單 屋苑入傳單 屋苑派傳單 屋苑入信箱 私樓派傳單 私樓入傳單 私樓入信箱 街頭派傳單 工商廈入傳單 工廈入傳單 商廈入傳單 派贈品 派sample 放易拉架 貼海報 貼街招 公屋派傳單 派通函 入通函 掛banner 放banner 合適行業 餐廳 補習社 茶飲 工程公司 太陽能公司 二餸飯 零售 美容儀器 裝修工程 防水工程 鋁窗工程 地產代理 保險代理 產品宣傳 品牌宣傳 電腦維修 食堂宣傳 宣傳易派傳單公司 WhatsApp: 94518014 https://api.whatsapp.com/send?phone=85294518014 承接全港各區派傳單.貼海報街招服務 我們的網站 https://myeasypromotion.com/ 我們的客戶 https://myeasypromotion.com/%e6%88%91%e5%80%91%e7%9a%84%e5%ae%a2%e6%88%b6/ 印傳單 https://myeasypromotion.com/%E5%8D%B0%E5%88%B7%E6%9C%8D%E5%8B%99/ Facebook 專頁 https://www.facebook.com/share/19Vz17DbxX/ 旋轉拍賣商店 https://carousell.app.link/me5wd2PN5Vb 海報宣傳 •••••••••••••••• 街上貼街招/貼海報 海報宣傳 全港各區, 每區300張起接, 提供影相為證服務. ⭕A4每區 300張起（每張$1.8） ⭕A5每區300張起(每張$1.2） ⭕A6每區300張起（每張$ 1) ⭕每張:A3/5 $ ; A2 /5.5 $ ; A1/ 6.5$ 每區 300張 貼村屋範圍街招海報 海報會全部拍攝相片 街招拍攝35張相片 . •••••••••••••••••• 洗樓入公屋 (上樓派傳單) 每張 0.65 1000張起 會拍攝150張相片 工商廈洗樓 舊式工商廈 會拍攝 35張相片證明 150元3座 130元 5座 120元 10座 110元20座 95元 30座 ⭕入村屋地下信箱 ：$270起接單 每區最少300戶起x9毫子 ⭕入唐樓地下信箱：$180 起接單 每區最少300戶起.x6毫子 汽車派傳單 派名片 的士或call 車平台公司或汽車美容公司 優惠 1.5 1張 放置 banner 掛banner 街頭放bannet 已申請地政署獲批放置 包取貨 10條以下 120元條 20條起 100元1條 要有放資詳細資料 code 會影相證明 偏遠地或 加 30元 1條 街上(舉牌)派傳單服務： 派傳單 2小時起 85元1小時 派傳單 3小時 80元 1小時 派傳單 4小時起 80元1小時 舉牌放傳單 加 10元1小時 加易拉架 加25元1小時 著制服 加 20元1小時 半山學校 加80元 1小時 派贈品 派飲品 派試用裝 派香水 派樣本 派sample 派公屋信箱 已申請入信箱 200戶 70元 每座 元 500戶 125元 750戶 188元 1000戶 250元. 最小 5 座起 已成功申請入公屋通函 誠意合作：WhatsApp: 94518014 派傳單，貼海報，貼街招 洗樓派傳單. 工廈商廈洗樓和私人屋苑,村屋，唐樓等入信箱服務. 印傳單 光粉紙 115克 210*285mm 2000張 需帶稿件 包本地送貨 460元 A4 尺寸 2000張 430元 A4 尺寸 4000張 660元 其後每 1000張 100元 A5 2000張 330元 A5 4000張 530元 其後每 1000張 100元 A6 2000張 300元 其後 每1000張80元 包送貨 印刷 A3. 海報 300張起 2.4元張 印刷 A2 海報 600張起 3元張 印刷 A1 海報 128克紙 600張起 3.4元 張 印刷 A1 海報 115克紙 700張 3元 #派傳單 #傳單員 #派傳單公司 #傳單印刷 #推廣員 #Promoter #印傳單 #派報公司 #投遞信箱 #發傳單 #發名片 #唐樓派傳單 #公屋派傳單 #貼海報 #貼街招 #貼貼紙 #全港專業洗樓派傳單 #派樓及印刷服務 #派傳單服務 #洗樓 #市場推廣 #宣傳 #派傳單服務 #海報宣傳 #派傳單 #推廣 #宣傳 #廣告 #Promotion #村屋派傳單 #車輛派傳單 #汽車派傳單 #村屋派信箱 #唐樓派信箱 #舊樓派傳單 #舊樓派信箱 # 工商廈派傳單 | F14: https://video.fagc3-2.fna.fbcdn.net/o1/v/t2/f2/m366/AQOXPceUZS7beoL2CRcri6BKiSy1-YEQP1iGyMVjsWNP6Js0W13-NztNF3R0hQ6CmaSsI3JMCpeNlFC-i6a4PHTi2mJkMyEaEsOUcf1gMEohNw.mp4?_nc_cat=104&_nc_oc=AdrsOGqlFs8nsj8ti85SUN2_q0UDXkv5Bo4aV_53ErhDq217S7E-kZ5l9zyeB1QZIU8&_nc_sid=5e9851&_nc_ht=video.fagc3-2.fna.fbcdn.net&_nc_ohc=ZyKi1xxHFMUQ7kNvwEEdztP&efg=eyJ2ZW5jb2RlX3RhZyI6Inhwdl9wcm9ncmVzc2l2ZS5GQUNFQk9PSy4uQzMuMTA4OC5kYXNoX2gyNjQtYmFzaWMtZ2VuMl83MjBwIiwieHB2X2Fzc2V0X2lkIjo4ODk3OTczNjQxMjAwODMsImFzc2V0X2FnZV9kYXlzIjoxNSwidmlfdXNlY2FzZV9pZCI6MTAxMjEsImR1cmF0aW9uX3MiOjE2NCwidXJsZ2VuX3NvdXJjZSI6Ind3dyJ9&ccb=17-1&vs=6e714a85334d8a82&_nc_vs=HBksFQIYRWZiX2VwaGVtZXJhbC81MzQ4NTAxQzI3NTBBRUFDQ0I4MTRENTI3NkYzQzhBNl9tdF8xX3ZpZGVvX2Rhc2hpbml0Lm1wNBUAAsgBEgAVAhhAZmJfcGVybWFuZW50L0MyNDQwRjM1NjQyMTZBN0YwQzlDMzcyMjMzMUNEMEEyX2F1ZGlvX2Rhc2hpbml0Lm1wNBUCAsgBEgAoABgAGwKIB3VzZV9vaWwBMRJwcm9ncmVzc2l2ZV9yZWNpcGUBMRUAACam6Pv8gtGUAxUCKAJDMywXQGSQo9cKPXEYGWRhc2hfaDI2NC1iYXNpYy1nZW4yXzcyMHARAHUCZZKeAQA&_nc_gid=lalNyvLnisdorAjl4SJoBA&_nc_ss=72289&_nc_zt=28&oh=00_Af7UYD546eT1ZTbg-3Kxu8UzIRvLQLHtZpvDfvz7kEnXKA&oe=6A10AAB0&bitrate=184413&tag=dash_h264-basic-gen2_720p | H14: 中性 | I14: 陳述 | J14: 廣告/促銷 | K14: 廣告 | L14: 無關 | M14: null | N14: null | O14: null | P14: null | Q14: 0 | R14: 0 | S14: 0
A15: https://www.facebook.com/groups/366950274676457/permalink/1731783888193082/ | B15: 翡翠家 | C15: 46141 | E15: 承接 派傳單 貼海報 貼街招 掛橫額 掛banner 工商廈派傳單 印傳單 印街招 想宣傳又想慳荷包 平價宣傳 增加生意額 增加公司知名度 全港 貼海報 海報宣傳 印傳單 印海報 印街招 派傳單 街上派傳單 派發傳單 工商廈派傳單 商廈派傳單 工廈派傳單 屋苑入傳單 屋苑派傳單 屋苑入信箱 私樓派傳單 私樓入傳單 私樓入信箱 街頭派傳單 工商廈入傳單 工廈入傳單 商廈入傳單 派贈品 派sample 放易拉架 貼海報 貼街招 公屋派傳單 派通函 入通函 掛banner 放banner 合適行業 餐廳 補習社 茶飲 工程公司 太陽能公司 二餸飯 零售 美容儀器 裝修工程 防水工程 鋁窗工程 地產代理 保險代理 產品宣傳 品牌宣傳 電腦維修 食堂宣傳 宣傳易派傳單公司 WhatsApp: 94518014 https://api.whatsapp.com/send?phone=85294518014 承接全港各區派傳單.貼海報街招服務 我們的網站 https://myeasypromotion.com/ 我們的客戶 https://myeasypromotion.com/%e6%88%91%e5%80%91%e7%9a%84%e5%ae%a2%e6%88%b6/ 印傳單 https://myeasypromotion.com/%E5%8D%B0%E5%88%B7%E6%9C%8D%E5%8B%99/ Facebook 專頁 https://www.facebook.com/share/19Vz17DbxX/ 旋轉拍賣商店 https://carousell.app.link/me5wd2PN5Vb 海報宣傳 •••••••••••••••• 街上貼街招/貼海報 海報宣傳 全港各區, 每區300張起接, 提供影相為證服務. ⭕A4每區 300張起（每張$1.8） ⭕A5每區300張起(每張$1.2） ⭕A6每區300張起（每張$ 1) ⭕每張:A3/5 $ ; A2 /5.5 $ ; A1/ 6.5$ 每區 300張 貼村屋範圍街招海報 海報會全部拍攝相片 街招拍攝35張相片 . •••••••••••••••••• 洗樓入公屋 (上樓派傳單) 每張 0.65 1000張起 會拍攝150張相片 工商廈洗樓 舊式工商廈 會拍攝 35張相片證明 150元3座 130元 5座 120元 10座 110元20座 95元 30座 ⭕入村屋地下信箱 ：$270起接單 每區最少300戶起x9毫子 ⭕入唐樓地下信箱：$180 起接單 每區最少300戶起.x6毫子 汽車派傳單 派名片 的士或call 車平台公司或汽車美容公司 優惠 1.5 1張 放置 banner 掛banner 街頭放bannet 已申請地政署獲批放置 包取貨 10條以下 120元條 20條起 100元1條 要有放資詳細資料 code 會影相證明 偏遠地或 加 30元 1條 街上(舉牌)派傳單服務： 派傳單 2小時起 85元1小時 派傳單 3小時 80元 1小時 派傳單 4小時起 80元1小時 舉牌放傳單 加 10元1小時 加易拉架 加25元1小時 著制服 加 20元1小時 半山學校 加80元 1小時 派贈品 派飲品 派試用裝 派香水 派樣本 派sample 派公屋信箱 已申請入信箱 200戶 70元 每座 元 500戶 125元 750戶 188元 1000戶 250元. 最小 5 座起 已成功申請入公屋通函 誠意合作：WhatsApp: 94518014 派傳單，貼海報，貼街招 洗樓派傳單. 工廈商廈洗樓和私人屋苑,村屋，唐樓等入信箱服務. 印傳單 光粉紙 115克 210*285mm 2000張 需帶稿件 包本地送貨 460元 A4 尺寸 2000張 430元 A4 尺寸 4000張 660元 其後每 1000張 100元 A5 2000張 330元 A5 4000張 530元 其後每 1000張 100元 A6 2000張 300元 其後 每1000張80元 包送貨 印刷 A3. 海報 300張起 2.4元張 印刷 A2 海報 600張起 3元張 印刷 A1 海報 128克紙 600張起 3.4元 張 印刷 A1 海報 115克紙 700張 3元 #派傳單 #傳單員 #派傳單公司 #傳單印刷 #推廣員 #Promoter #印傳單 #派報公司 #投遞信箱 #發傳單 #發名片 #唐樓派傳單 #公屋派傳單 #貼海報 #貼街招 #貼貼紙 #全港專業洗樓派傳單 #派樓及印刷服務 #派傳單服務 #洗樓 #市場推廣 #宣傳 #派傳單服務 #海報宣傳 #派傳單 #推廣 #宣傳 #廣告 #Promotion #村屋派傳單 #車輛派傳單 #汽車派傳單 #村屋派信箱 #唐樓派信箱 #舊樓派傳單 #舊樓派信箱 # 工商廈派傳單 | F15: https://video.fagc3-1.fna.fbcdn.net/o1/v/t2/f2/m366/AQO8Bhr0LcpKkLechE2_dTjwenirJJYa0z1YZ_ymyGIKEuWcDMcYVtsylnjSRFuG4c1bLCpQ0YF4Aisy2P8qd-v1yXhdcdFUx3GOX10WEQTW7g.mp4?_nc_cat=102&_nc_oc=Adr56FMCZSGluLiDK6_RmBi4_rjPGK_PeQ63lYg3CF-BrDrTSD_Yh91BDTiqcYXi6mE&_nc_sid=5e9851&_nc_ht=video.fagc3-1.fna.fbcdn.net&_nc_ohc=FMtvX5OGnUcQ7kNvwFJKGi0&efg=eyJ2ZW5jb2RlX3RhZyI6Inhwdl9wcm9ncmVzc2l2ZS5GQUNFQk9PSy4uQzMuMTA4OC5kYXNoX2gyNjQtYmFzaWMtZ2VuMl83MjBwIiwieHB2X2Fzc2V0X2lkIjoxNDgzNzE4NjY2NzI3Mjc5LCJhc3NldF9hZ2VfZGF5cyI6MTgsInZpX3VzZWNhc2VfaWQiOjEwMTIxLCJkdXJhdGlvbl9zIjoxNjQsInVybGdlbl9zb3VyY2UiOiJ3d3cifQ%3D%3D&ccb=17-1&vs=7198388bdb5b1488&_nc_vs=HBksFQIYRWZiX2VwaGVtZXJhbC8wNTQ2QUE1MkE0NzI4NkI5MDNCQjc5OUQyMzk3NEJBNl9tdF8xX3ZpZGVvX2Rhc2hpbml0Lm1wNBUAAsgBEgAVAhhAZmJfcGVybWFuZW50LzQyNEUzRUI3MjdCOTU0MEE1RjIwMTg2NjhFNkU3RDkwX2F1ZGlvX2Rhc2hpbml0Lm1wNBUCAsgBEgAoABgAGwKIB3VzZV9vaWwBMRJwcm9ncmVzc2l2ZV9yZWNpcGUBMRUAACbevZ3B5duiBRUCKAJDMywXQGSQo9cKPXEYGWRhc2hfaDI2NC1iYXNpYy1nZW4yXzcyMHARAHUCZZKeAQA&_nc_gid=lalNyvLnisdorAjl4SJoBA&_nc_ss=72289&_nc_zt=28&oh=00_Af5M8i-oL1HNrEfr3Be3xO6cfZBHa_oP4MySIyEjulwjWA&oe=6A10A746&bitrate=184413&tag=dash_h264-basic-gen2_720p | H15: 中性 | I15: 陳述 | J15: 廣告/促銷 | K15: 廣告 | L15: 無關 | M15: null | N15: null | O15: null | P15: null | Q15: 0 | R15: 0 | S15: 0
A16: https://www.facebook.com/groups/366950274676457/permalink/1730649444973193/ | B16: 翡翠家 | C16: 46140 | E16: 承接 派傳單 貼海報 貼街招 掛橫額 掛banner 工商廈派傳單 印傳單 印街招 想宣傳又想慳荷包 平價宣傳 增加生意額 增加公司知名度 全港 貼海報 海報宣傳 印傳單 印海報 印街招 派傳單 街上派傳單 派發傳單 工商廈派傳單 商廈派傳單 工廈派傳單 屋苑入傳單 屋苑派傳單 屋苑入信箱 私樓派傳單 私樓入傳單 私樓入信箱 街頭派傳單 工商廈入傳單 工廈入傳單 商廈入傳單 派贈品 派sample 放易拉架 貼海報 貼街招 公屋派傳單 派通函 入通函 掛banner 放banner 合適行業 餐廳 補習社 茶飲 工程公司 太陽能公司 二餸飯 零售 美容儀器 裝修工程 防水工程 鋁窗工程 地產代理 保險代理 產品宣傳 品牌宣傳 電腦維修 食堂宣傳 宣傳易派傳單公司 WhatsApp: 94518014 https://api.whatsapp.com/send?phone=85294518014 承接全港各區派傳單.貼海報街招服務 我們的網站 https://myeasypromotion.com/ 我們的客戶 https://myeasypromotion.com/%e6%88%91%e5%80%91%e7%9a%84%e5%ae%a2%e6%88%b6/ 印傳單 https://myeasypromotion.com/%E5%8D%B0%E5%88%B7%E6%9C%8D%E5%8B%99/ Facebook 專頁 https://www.facebook.com/share/19Vz17DbxX/ 旋轉拍賣商店 https://carousell.app.link/me5wd2PN5Vb 海報宣傳 •••••••••••••••• 街上貼街招/貼海報 海報宣傳 全港各區, 每區300張起接, 提供影相為證服務. ⭕A4每區 300張起（每張$1.8） ⭕A5每區300張起(每張$1.2） ⭕A6每區300張起（每張$ 1) ⭕每張:A3/5 $ ; A2 /5.5 $ ; A1/ 6.5$ 每區 300張 貼村屋範圍街招海報 海報會全部拍攝相片 街招拍攝35張相片 . •••••••••••••••••• 洗樓入公屋 (上樓派傳單) 每張 0.65 1000張起 會拍攝150張相片 工商廈洗樓 舊式工商廈 會拍攝 35張相片證明 150元3座 130元 5座 120元 10座 110元20座 95元 30座 ⭕入村屋地下信箱 ：$270起接單 每區最少300戶起x9毫子 ⭕入唐樓地下信箱：$180 起接單 每區最少300戶起.x6毫子 汽車派傳單 派名片 的士或call 車平台公司或汽車美容公司 優惠 1.5 1張 放置 banner 掛banner 街頭放bannet 已申請地政署獲批放置 包取貨 10條以下 120元條 20條起 100元1條 要有放資詳細資料 code 會影相證明 偏遠地或 加 30元 1條 街上(舉牌)派傳單服務： 派傳單 2小時起 85元1小時 派傳單 3小時 80元 1小時 派傳單 4小時起 80元1小時 舉牌放傳單 加 10元1小時 加易拉架 加25元1小時 著制服 加 20元1小時 半山學校 加80元 1小時 派贈品 派飲品 派試用裝 派香水 派樣本 派sample 派公屋信箱 已申請入信箱 200戶 70元 每座 元 500戶 125元 750戶 188元 1000戶 250元. 最小 5 座起 已成功申請入公屋通函 誠意合作：WhatsApp: 94518014 派傳單，貼海報，貼街招 洗樓派傳單. 工廈商廈洗樓和私人屋苑,村屋，唐樓等入信箱服務. 印傳單 光粉紙 115克 210*285mm 2000張 需帶稿件 包本地送貨 460元 A4 尺寸 2000張 430元 A4 尺寸 4000張 660元 其後每 1000張 100元 A5 2000張 330元 A5 4000張 530元 其後每 1000張 100元 A6 2000張 300元 其後 每1000張80元 包送貨 印刷 A3. 海報 300張起 2.4元張 印刷 A2 海報 600張起 3元張 印刷 A1 海報 128克紙 600張起 3.4元 張 印刷 A1 海報 115克紙 700張 3元 #派傳單 #傳單員 #派傳單公司 #傳單印刷 #推廣員 #Promoter #印傳單 #派報公司 #投遞信箱 #發傳單 #發名片 #唐樓派傳單 #公屋派傳單 #貼海報 #貼街招 #貼貼紙 #全港專業洗樓派傳單 #派樓及印刷服務 #派傳單服務 #洗樓 #市場推廣 #宣傳 #派傳單服務 #海報宣傳 #派傳單 #推廣 #宣傳 #廣告 #Promotion #村屋派傳單 #車輛派傳單 #汽車派傳單 #村屋派信箱 #唐樓派信箱 #舊樓派傳單 #舊樓派信箱 # 工商廈派傳單 | F16: https://video-ord5-1.xx.fbcdn.net/o1/v/t2/f2/m366/AQN5dkhpO3bCulSKfZNTCZamUAgW0qwTq4qp7SQGp65J08EeGwAJ6IUePRcgdE-Ug1k6C5MeyGhJFZCzMdSgZHEhYfXO-x1Z0zeRfA31qB25gQ.mp4?_nc_cat=101&_nc_sid=5e9851&_nc_ht=video-ord5-1.xx.fbcdn.net&_nc_ohc=PFNSPELsRgAQ7kNvwFOoEFJ&efg=eyJ2ZW5jb2RlX3RhZyI6Inhwdl9wcm9ncmVzc2l2ZS5GQUNFQk9PSy4uQzMuMTA4OC5kYXNoX2gyNjQtYmFzaWMtZ2VuMl83MjBwIiwieHB2X2Fzc2V0X2lkIjo5NDgzMzEzMzc4MDAwODcsImFzc2V0X2FnZV9kYXlzIjoxOSwidmlfdXNlY2FzZV9pZCI6MTAxMjEsImR1cmF0aW9uX3MiOjE2NCwidXJsZ2VuX3NvdXJjZSI6Ind3dyJ9&ccb=17-1&vs=1889844cdedbeb47&_nc_vs=HBksFQIYRWZiX2VwaGVtZXJhbC9DMzQ2MUU1MEQzRkMyNzJDQkZDMjRBMjYzRUU1RTFBRl9tdF8xX3ZpZGVvX2Rhc2hpbml0Lm1wNBUAAsgBEgAVAhhAZmJfcGVybWFuZW50L0ZBNEJDREY1OTZCNUM3NTY3RTVCOUM3QzgzNTJEM0I5X2F1ZGlvX2Rhc2hpbml0Lm1wNBUCAsgBEgAoABgAGwKIB3VzZV9vaWwBMRJwcm9ncmVzc2l2ZV9yZWNpcGUBMRUAACau5qaIk6CvAxUCKAJDMywXQGSQo9cKPXEYGWRhc2hfaDI2NC1iYXNpYy1nZW4yXzcyMHARAHUCZZKeAQA&_nc_gid=zptLeguYWVWdO1tJhQkW3Q&_nc_ss=72289&_nc_zt=28&oh=00_Af5l8V9H097AYQNvyOkjMqffBp7hXaXutdGSXi7ZE8h_Rw&oe=6A10A13B&bitrate=184413&tag=dash_h264-basic-gen2_720p | H16: 中性 | I16: 陳述 | J16: 其他 | K16: 廣告 | L16: 無關 | M16: null | N16: null | O16: null | P16: null | Q16: 0 | R16: 0 | S16: 0
A17: https://www.facebook.com/groups/366950274676457/permalink/1729719748399496/ | B17: 李美薇 | C17: 46139 | E17: ＃格林Greentrac 感謝支持 格林輪呔 --- - - - 銷售地點 港島區： 鴻記電池輪呔 香港田灣漁歌街3號地下 ☎️90455553 中國膠輪電池 幹諾道西160號 ☎️25480222 筲箕灣汽車唧油 香港筲箕灣新成街2號G H I舖 ☎️96089819 金威膠輪有限公司 柴灣豐業街12號 ☎️28978520 九龍區： 通明膠輪公司 觀塘通明街64號地下 ☎️2343 5516 金鋒汽車服務 九龍樂富靜安街36號地下 ☎️9523 1657 灝天輪呔 九龍深水埗海壇街166號地下 ☎️69708432 棠記膠輪 九龍深水埗福華街77號地下 ☎️9234 1185 新界區： 金威膠輪有限公司 沙田火炭坳背灣街53-55 號美高工業大廈地下A舖 ☎️26620588 新昌膠輪公司 上水嘉富坊貿易廣場B座地下5號 ☎️9837 9847 新金成膠輪電池公司 粉嶺安居街8號地下 ☎️2674 6144 大眾輪胎行 元朗媽橫路47號 ☎️2477 2356 萬昌行 屯門建泰街6號恒威工業中心地下155號 ☎️91333830 歐洲品牌格林輪胎 熱賣好評！德國技術，品質保證！ 多謝大家的支持‍♂️‍♂️！ 本公司繼續極力推薦使用 歐洲品牌 格林輪胎 進化科技 定義未來 高強度胎體設計,完美匹配，表現出精湛抓地力與轉向性能。 胎邊結構:雙層聚酯纖維 雙層胎邊結構設計,提供絕佳過彎支撐性能,給於胎面在彎道中保有最大摩擦面積,賦予極佳的安全性與操控性能 A級濕滑✅胎面特殊配方，直線紋路設計有效降低阻滾動噪音，提高濕地性能。 強力轉向✅胎圈特殊材料補強設計提升輪胎支撐性，同時為轉向性能提供強力保障。 ＃歐洲品牌 ＃格林輪胎 ＃Greentrac ＃舒適低噪音 ＃最大排水量 ＃高穩定性擋塊 ＃降低道路噪音 ＃超低滾動阻力 ＃燃油節省 ＃超高性能輪胎 Greentrac Quest-X UHP 超高性能輪胎 採用德國技術3D主動靜音設計！ 熱賣中 性價比高 一致讚好 持續發威 另備有多款專為私家車型號(格林輪呔) 滿足有要求的客人 歡迎各位查詢預約 ＃港澳總代理 ＃智盈實業 https://wa.me/85297840529 | H17: 正面 | I17: 滿意 | J17: 廣告/促銷 | K17: 廣告 | L17: 無關 | M17: 田灣,筲箕灣,柴灣,觀塘,樂富,深水埗,沙田火炭,上水,粉嶺,元朗,屯門 | N17: null | O17: null | P17: null | Q17: 0 | R17: 0 | S17: 0
A18: https://www.facebook.com/groups/366950274676457/permalink/1728247225213415/ | B18: Luk Kwok Ho | C18: 46137 | E18: 市場極小 4K + 4K sony 12吋全畫面（右眼）前後 4K sony鏡頭 $1480 包 64g卡 18個月保養 5g wifi 送gps定位 ( 送完即止 ) ~~~~~~~~~~~~~~~~ 真係要買啲 幾千蚊嘅cam 平貨都有質素嘅 #產品資料 https://www.facebook.com/share/1BvFA6A82o/ 前鏡頭4k 後鏡頭1080p 隱蔽式$380 倒後鏡$430 包32G卡 (一年保養) #最高清產品 前4k後2k $580 包32G卡 (一年保養) #商務車輛必備 三鏡頭 $530 4K+1080P+1080P 包32G卡 (一年保養） #10寸 全畫面 倒後鏡 三鏡頭 前3K中後1080P $580 包32g記憶卡 (一年保養) #高要求首選 最高清 市場極小 前4k後4k sony 鏡頭 $1280 包64g (18個月保養) #12寸全畫面前後錄影 前後外掛sony鏡頭 前2k後2k $980 包64g 18個月保養 #12寸 全畫面 (右眼) 前後 双4K sony鏡頭 $1480 包 64g 18個月保養 ( 前鏡頭跟主機 ) #4G遠程 你這剎那在何方 都可以即時觀看車輛環境 2K + 1080P #須自備sim卡 $680包64g卡 一年保養 #跟兩款電源線 煙插 or 24小時 fuse #wifi手機連接下載 #如果需要安裝人工 $500 - $600 安裝地址 #大角咀洋松街 GPS https://maps.app.goo.gl/7VKGEnVbLzEZ8mTm7?g_st=awb Whatsapp https://api.whatsapp.com/send?phone=85290494941 #屯門良田村 GPS https://maps.app.goo.gl/PLUcXzdT43qFdzR66?g_st=awb Whatsapp https://api.whatsapp.com/send?phone=85269988527 #天水圍田廈路 GPS https://maps.app.goo.gl/UFs1rsR2VBqSLB2A8?g_st=awb whatsapp https://api.whatsapp.com/send?phone=85266883466 #大埔車迷 GPS https://maps.app.goo.gl/dDJxdU79aWy3CELG7?g_st=awb Whatsapp https://api.whatsapp.com/send?phone=85226383365 #旺角黑布街 gps https://maps.app.goo.gl/HNBaAr6YvVJtsxJg8?g_st=awb whatsapp https://api.whatsapp.com/send?phone=85297770066 #和宜合道255號 Gps https://maps.app.goo.gl/6DQMvNVX1LX6LGu48?g_st=awb Whatsapp https://api.whatsapp.com/send?phone=85292209738 #九龍黃大仙竹園翠鳳街19號地下 LAAM LOK car service Gps https://maps.app.goo.gl/TKNjQ2wRPNcRSf9u7?g_st=awb Whatsapp https://api.whatsapp.com/send?phone=85254992828 #新界九龍上門安裝 700蚊費用 中午12 至 夜晚10 whatsapp https://api.whatsapp.com/send?phone=85226383365 #不需要安裝新界九龍面交 中午12 至 夜晚12 有意請whatsapp了解 按下去就是我的whatsapp https://api.whatsapp.com/send?phone=85260326500 #車cam #4K #1080p #前後cam #toyota #honda #nissan #mitsubishi #audi #vw #benz #kia #bmw #byd #Tesla | H18: 中性 | I18: 陳述 | J18: 廣告/促銷 | K18: 廣告 | L18: 無關 | M18: 大角咀洋松街, 屯門良田村, 天水圍田廈路, 大埔, 旺角黑布街, 和宜合道255號, 九龍黃大仙竹園翠鳳街19號 | N18: null | O18: null | P18: null | Q18: 0 | R18: 0 | S18: 0
A19: https://www.facebook.com/groups/366950274676457/permalink/1727408728630598/ | B19: Jack Chan | C19: 46136 | E19: 又有優惠啦！！！ 佐敦高臨停車場，電動車月租優惠！$3800 | G19: https://scontent-bos5-1.xx.fbcdn.net/v/t39.30808-6/677761721_122202717134581123_1503788171277941040_n.jpg?stp=cp6_dst-jpg_s960x960_tt6&_nc_cat=102&ccb=1-7&_nc_sid=aa7b47&_nc_ohc=qOw2sZj-IcAQ7kNvwFKoh2I&_nc_oc=Ado6Qbk18dLhY5bv57mSZRGLkNZvKZfNF9VKL6q_VCo2yfzphdn0DW6dk5oEOL8xA8gh0HUguJj7B1kh8v4G7F4h&_nc_zt=23&_nc_ht=scontent-bos5-1.xx&_nc_gid=YkxMDG4iCmDQ2HuJb-vyzQ&_nc_ss=72289&oh=00_Af55O--TkEycQOPQL_8R9DUAV2-f6BoHyfNF6duCYq5_3g&oe=6A109B03 | H19: 正面 | I19: 開心 | J19: 收費/價錢 | K19: 廣告 | L19: 直接相關 | M19: 佐敦高臨停車場 | N19: null | O19: null | P19: null | Q19: 3 | R19: 0 | S19: 1
A20: https://www.facebook.com/groups/366950274676457/permalink/1723420689029402/ | B20: BlueLobster8261 | C20: 46131 | E20: 我不入地獄誰入地獄 https://share.google/k0d5A5WSK45Qnz1a0 | G20: https://scontent-bos5-1.xx.fbcdn.net/v/t39.30808-6/672710893_2055785651671802_6852572690524723594_n.jpg?stp=dst-jpg_p526x296_tt6&_nc_cat=103&ccb=1-7&_nc_sid=aa7b47&_nc_ohc=T9A5Q9r_3pYQ7kNvwG-_zTx&_nc_oc=AdqhuTe8DpElWsIftbpZE7g0vX88y-2gE6jULyz5AHofTI7_L7oSKjjQ1N-AJo5qPdVqKrO8Y89ziyE2f9w0dONx&_nc_zt=23&_nc_ht=scontent-bos5-1.xx&_nc_gid=YkxMDG4iCmDQ2HuJb-vyzQ&_nc_ss=72289&oh=00_Af6kRAUH_vytmVmbzUH7nVbxoNrKfwp6-i57sff1VDOaLw&oe=6A10A07A | H20: 中性 | I20: 陳述 | J20: 其他 | K20: 純分享 | L20: 無關 | M20: null | N20: null | O20: null | P20: null | Q20: 0 | R20: 0 | S20: 0
A21: https://www.facebook.com/groups/366950274676457/permalink/1721648979206573/ | B21: Ann Lee | C21: 46129 | E21: ＃格林Greentrac 感謝支持 格林輪呔 --- - - - 銷售地點 港島區： 鴻記電池輪呔 香港田灣漁歌街3號地下 ☎️90455553 中國膠輪電池 幹諾道西160號 ☎️25480222 筲箕灣汽車唧油 香港筲箕灣新成街2號G H I舖 ☎️96089819 金威膠輪有限公司 柴灣豐業街12號 ☎️28978520 九龍區： 通明膠輪公司 觀塘通明街64號地下 ☎️2343 5516 金鋒汽車服務 九龍樂富靜安街36號地下 ☎️9523 1657 灝天輪呔 九龍深水埗海壇街166號地下 ☎️69708432 棠記膠輪 九龍深水埗福華街77號地下 ☎️9234 1185 新界區： 金威膠輪有限公司 沙田火炭坳背灣街53-55 號美高工業大廈地下A舖 ☎️26620588 新昌膠輪公司 上水嘉富坊貿易廣場B座地下5號 ☎️9837 9847 新金成膠輪電池公司 粉嶺安居街8號地下 ☎️2674 6144 大眾輪胎行 元朗媽橫路47號 ☎️2477 2356 萬昌行 屯門建泰街6號恒威工業中心地下155號 ☎️91333830 歐洲品牌格林輪胎 熱賣好評！德國技術，品質保證！ 多謝大家的支持‍♂️‍♂️！ 本公司繼續極力推薦使用 歐洲品牌 格林輪胎 進化科技 定義未來 高強度胎體設計,完美匹配，表現出精湛抓地力與轉向性能。 胎邊結構:雙層聚酯纖維 雙層胎邊結構設計,提供絕佳過彎支撐性能,給於胎面在彎道中保有最大摩擦面積,賦予極佳的安全性與操控性能 A級濕滑✅胎面特殊配方，直線紋路設計有效降低阻滾動噪音，提高濕地性能。 強力轉向✅胎圈特殊材料補強設計提升輪胎支撐性，同時為轉向性能提供強力保障。 ＃歐洲品牌 ＃格林輪胎 ＃Greentrac ＃舒適低噪音 ＃最大排水量 ＃高穩定性擋塊 ＃降低道路噪音 ＃超低滾動阻力 ＃燃油節省 ＃超高性能輪胎 Greentrac Quest-X UHP 超高性能輪胎 採用德國技術3D主動靜音設計！ 熱賣中 性價比高 一致讚好 持續發威 另備有多款專為私家車型號(格林輪呔) 滿足有要求的客人 歡迎各位查詢預約 ＃港澳總代理 ＃智盈實業 https://wa.me/85297840529 | H21: 正面 | I21: 期待 | J21: 廣告/促銷 | K21: 廣告 | L21: 無關 | M21: 田灣,筲箕灣,柴灣,觀塘,樂富,深水埗,沙田火炭,上水,粉嶺,元朗,屯門 | N21: null | O21: null | P21: null | Q21: 0 | R21: 0 | S21: 0
A22: https://www.facebook.com/groups/366950274676457/permalink/1720152196022918/ | B22: 李漢民 | C22: 46127 | E22: 【車友警示】小心 Shell Recharge 變相加價！快充 60kW 變 30kW 的收費把戲！ 各位車友，入去 Shell 充電站前請三思！今日喺機場貨運大樓 Shell Recharge 遇到極之離譜嘅收費同技術問題，大家一定要小心以下「三招」： 1️⃣ 「文字遊戲」：標榜 60kW，實質 30kW App 入面大大字寫住最高速度 60kW，但原來只要隔離有車一齊充，佢就會自動減速。我實測部車顯示只入到 30kW！客服起初仲想推卸責任話係部車「唔吸電」，最後被我踢爆先肯承認係因為兩支槍分流導致輸出減半。 2️⃣ 「低消陷阱」：速度減慢，最低消費照收 最無良嘅係，佢速度減半令你充多一倍時間，但依然設有 HKD 80 的最低消費。當你發現充得慢想中途停手，佢一樣收足你 $80。計返埋單，每度電嘅平均單價貴到離譜，完全係變相加價！ 3️⃣ 「計算混亂」：客服口風轉完又轉 我充咗 12.3 kWh，按原價 $3.9/kWh 應該只係 $48 左右，但因為嗰個「最低消費」加上佢哋補償計算不清，搞到收費極度唔透明。雖然最後嘈到佢哋話退返 $30.8 同加 $20 心意金，但呢種「你要嘈先肯退」嘅態度真係令人好失望。 ⚠️ 溫馨提示： 如果大家趕時間，或者唔想被扣冤枉錢，見到隔離有車充電就千祈唔好入去 Shell 呢啲「共享功率」嘅充電位。佢哋嘅銷售標語極具誤導性，明明係慢充速度，卻收快充嘅價錢！ #ShellRecharge #香港電車 #EVHK #充電陷阱 #機場充電 #快充變慢充 #消費者權益 | H22: 負面 | I22: 生氣 | J22: 收費/價錢 | K22: 純分享 | L22: 直接相關 | M22: 機場 | N22: null | O22: Shell Recharge | P22: 60kW, 30kW, 快充, 慢充 | Q22: 151 | R22: 101 | S22: 2
A23: https://www.facebook.com/groups/366950274676457/permalink/1720179539353517/ | B23: Anonymous participant | C23: 46127 | E23: 各位師兄 細佬我想問一問 屯門邊到有叉電平靚正？ | H23: 中性 | I23: 疑問 | J23: 疑問/求助 | K23: 求助 | L23: 直接相關 | M23: 屯門 | N23: null | O23: null | P23: null | Q23: 0 | R23: 6 | S23: 0
A24: https://www.facebook.com/groups/366950274676457/permalink/1718688556169282/ | B24: Roy Ng | C24: 46125 | E24: 八鄉汽車美容 公司位置： 錦田八鄉橫台山 （順利行格離） 如有興趣或其他汽車美容 詳情或預約 可聯絡☎️51992395 賢 ☎️ https://m.facebook.com/八鄉汽車美容-洗車-打蠟-蒸籠-140889456736875 日本9H 白金塗層復合鍍膜 1-2年期 深層研磨去漬拋光 除花痕去蜘蛛紋 鍍晶水腊人手泡抹洗車 推泥膠 去污 凡惠昌顧9H塗層鍍鏌加送 納米空氣觸媒消毒蒸籠 冷氣殺菌消毒服務 ⛔️半年保養⛔️ 現優惠價2️⃣5️⃣0️⃣0️⃣ （全車深層清潔消毒套餐 ） 鍍晶水腊 人手泡抹洗車 推泥膠 去污 ➕吸塵 洗鈴 清潔玻璃 ➕ 霧化藥水消毒 除甲醛 除味 防霉 ➕ 藥水泡泡深層清潔內籠 ➕納米空氣觸媒殺菌消毒除味 ➕冷氣殺菌消毒服務 現優惠價 9️⃣5️⃣0️⃣ （ 跣水3M三重水晶蠟消毒蒸籠套餐 ） 鍍晶水腊 人手泡抹洗車 推泥膠 去污 ➕ 吸塵 口清潔玻璃 洗鈴 ➕ 冷氣霧化消毒 除甲醛 除味 防霉 ➕火三層3M水晶蠟（深度去漬去花拋光） ➕藥水泡泡深層清潔內籠 ➕納米空氣觸媒殺菌消毒除味 ➕冷氣殺菌消毒服務 現優惠價 1️⃣8️⃣8️⃣8️⃣ 以下個別項目因應車輛大小 有所調整 以下是各式單項服務及價錢 A :鍍晶水腊 人手洗車 泥膠 內籠吸塵清潔 洗鈴 1️⃣4️⃣8️⃣起 B：納米空氣觸媒霧化消毒 內籠連冷氣 除菌 除味防霉 4️⃣2️⃣0️⃣起 C：藥水泡泡深層清潔蒸籠 包吸塵 （座位 座位底 尾箱 冷氣口 地毯） 4️⃣8️⃣0️⃣起 D: 一層3M打蠟（拋光 輕度去花去漬） 洗車 吸塵 推泥膠 洗鈴及清潔玻璃 5️⃣0️⃣0️⃣ E: 跣水3M三重水晶蠟 （深度去花去漬拋光水晶臘） 洗車 吸塵 推泥膠 洗鈴及清潔玻璃 9️⃣8️⃣8️⃣ 起 F: 玻璃鍍晶 線水 去油面 污漬 5️⃣0️⃣0️⃣起 G: 清洗引擎箱 3️⃣0️⃣0️⃣ H: 頭燈翻新（一對） 6️⃣0️⃣0️⃣ #洗車 #打臘 #汽車美容 #蒸籠 #除味消毒 #八鄉汽車美容 #去漬 #9H鍍鏌 #內籠清潔 #打腊 #霧化消毒 #拋光 #去花痕 #元朗 #保護層 #撥水 | H24: 中性 | I24: 陳述 | J24: 廣告/促銷 | K24: 廣告 | L24: 無關 | M24: 八鄉 | N24: null | O24: null | P24: null | Q24: 0 | R24: 0 | S24: 0
A25: https://www.facebook.com/groups/366950274676457/permalink/1717680312936773/ | B25: 陳傲輝 | C25: 46124 | E25: 有見到你架電車做的士未？ 大熱byd 竟然少過mifa7 | H25: 中性 | I25: 疑問 | J25: 資訊分享 | K25: 純分享 | L25: 直接相關 | M25: null | N25: BYD, MIFA7 | O25: null | P25: null | Q25: 0 | R25: 0 | S25: 0
A26: https://www.facebook.com/groups/366950274676457/permalink/1716559856382152/ | B26: LoyalElephant5591 | C26: 46122 | E26: 成日無電 元朗呢個新潭路三號電站，唔知點解朝早成日都會停電，係咪被人差曬啲電？無電賣？ | G26: https://scontent-dfw5-2.xx.fbcdn.net/v/t39.30808-6/668712945_993325249925828_1842925722426541292_n.jpg?stp=cp6_dst-jpg_p180x540_tt6&_nc_cat=100&ccb=1-7&_nc_sid=aa7b47&_nc_ohc=nuZghVGqVQAQ7kNvwF71fZn&_nc_oc=AdrGbf2rP9nuu0J6Q_Cix1XdakmNtsETJ-qX-ZpY-RzsY1pS70g31KIjZKZDJ1ySiVs&_nc_zt=23&_nc_ht=scontent-dfw5-2.xx&_nc_gid=TC7hPaUniuFmHQh6Vk2hiQ&_nc_ss=72289&oh=00_Af5fzOAJtNI5aeBgZJPnDE-1DbAr0vUbcSzuvJk0Kj6-yw&oe=6A10B5CF | H26: 負面 | I26: 失望 | J26: 充電站設施/位置 | K26: 純分享 | L26: 直接相關 | M26: 元朗新潭路 | N26: null | O26: null | P26: null | Q26: 32 | R26: 25 | S26: 0
A27: https://www.facebook.com/groups/366950274676457/permalink/1715215686516569/ | B27: Tommy Lo | C27: 46121 | E27: 偉業街洗車加充電一站過可以淨充電 日頭都係2.5一度 洗車都係，全部都係次次清俾八達通 唔需要套票或者充值一百值得推薦 | H27: 正面 | I27: 滿意 | J27: 收費/價錢 | K27: 純分享 | L27: 直接相關 | M27: 偉業街 | N27: null | O27: null | P27: null | Q27: 73 | R27: 35 | S27: 1
A28: https://www.facebook.com/groups/366950274676457/permalink/1709728790398592/ | B28: Ka Ka Chan | C28: 46114 | E28: Cornerstone 6折充電私放 有意請PM | H28: 中性 | I28: 陳述 | J28: 收費/價錢 | K28: 廣告 | L28: 直接相關 | M28: null | N28: null | O28: Cornerstone | P28: null | Q28: 0 | R28: 3 | S28: 0
A29: https://www.facebook.com/groups/366950274676457/permalink/1704122087625929/ | B29: Ka Ka Lam | C29: 46107 | E29: 尚翹峰灣仔街市停車場，新安裝左充電機， 以後食飯買餸又可以充電，真係好方便啊～ | G29: https://scontent-lga3-1.xx.fbcdn.net/v/t39.30808-6/658398685_1299013122146964_7224062660589709086_n.jpg?stp=dst-jpg_s600x600_tt6&_nc_cat=103&ccb=1-7&_nc_sid=aa7b47&_nc_ohc=vDbxTkPgM8sQ7kNvwFd9n0d&_nc_oc=AdrYwVb4Ni9_MTkLN-KnSRwH6xVpuShq2QXDlWXBH6yep1wypXWEbiMD28pgnyO6d8I&_nc_zt=23&_nc_ht=scontent-lga3-1.xx&_nc_gid=3hK_bdqP4gD59nuNbioZwQ&_nc_ss=72289&oh=00_Af5QC4U1k117JK9ZYJvz8hs_DFD4imBjynLKMwnvLIxXSg&oe=6A109265 | H29: 正面 | I29: 開心 | J29: 充電站設施/位置 | K29: 純分享 | L29: 直接相關 | M29: 灣仔尚翹峰灣仔街市 | N29: null | O29: null | P29: null | Q29: 22 | R29: 5 | S29: 0
A30: https://www.facebook.com/groups/366950274676457/permalink/1696900318348106/ | B30: Jack Chan | C30: 46098 | E30: 佐敦西貢街月租停車場，地點方便，易泊 呢頭又多個選擇 | G30: https://scontent-lga3-3.xx.fbcdn.net/v/t39.30808-6/652379669_122197761530581123_7638020414330014135_n.jpg?stp=cp6_dst-jpg_s720x720_tt6&_nc_cat=106&ccb=1-7&_nc_sid=aa7b47&_nc_ohc=enRBHQ-ZwF8Q7kNvwHnlS7-&_nc_oc=Adqvvf25Zsc-9Y3o7pRqzwQGYGcw8axpvUTrJj666Bdso_h1EZLjDuNEJ0LzJkDyA9Q&_nc_zt=23&_nc_ht=scontent-lga3-3.xx&_nc_gid=h-bfZUZaPpmZp4tyPNuESQ&_nc_ss=72289&oh=00_Af7So2A1d6uuQ2LrscVewMJ1MJ1cQV8rYgGHHSZvAqh65A&oe=6A1094BA | H30: 正面 | I30: 滿意 | J30: 充電站設施/位置 | K30: 純分享 | L30: 間接相關 | M30: 佐敦西貢街 | N30: null | O30: null | P30: null | Q30: 4 | R30: 0 | S30: 1
A31: https://www.facebook.com/groups/366950274676457/permalink/1691833838854754/ | B31: King King | C31: 46092 | D31: This content isn't available right now | E31: ＃格林Greentrac 感謝支持 格林輪呔 --- - - - 銷售地點 港島區： 鴻記電池輪呔 香港田灣漁歌街3號地下 ☎️90455553 中國膠輪電池 幹諾道西160號 ☎️25480222 筲箕灣汽車唧油 香港筲箕灣新成街2號G H I舖 ☎️96089819 金威膠輪有限公司 柴灣豐業街12號 ☎️28978520 九龍區： 通明膠輪公司 觀塘通明街64號地下 ☎️2343 5516 金鋒汽車服務 九龍樂富靜安街36號地下 ☎️9523 1657 灝天輪呔 九龍深水埗海壇街166號地下 ☎️69708432 棠記膠輪 九龍深水埗福華街77號地下 ☎️9234 1185 新界區： 金威膠輪有限公司 沙田火炭坳背灣街53-55 號美高工業大廈地下A舖 ☎️26620588 新昌膠輪公司 上水嘉富坊貿易廣場B座地下5號 ☎️9837 9847 新金成膠輪電池公司 粉嶺安居街8號地下 ☎️2674 6144 大眾輪胎行 元朗媽橫路47號 ☎️2477 2356 萬昌行 屯門建泰街6號恒威工業中心地下155號 ☎️91333830 合各類型貨van，夠磅驗車 ＃各類型貨VAN ＃標緻貨van ＃TRAVELLER ＃平治貨van ＃BENZ ＃VITO ＃福特貨van ＃FORD ＃福士貨van ＃t5 ＃t6 ＃現代貨van ＃H1 ＃STARIA ＃豐田貨van ＃hiace200 ＃hiace300 ＃日産貨van ＃NV350 ＃E25 ＃E26 性價比之選，夠磅驗車 215/70/15，$680 215/65/16，$780 225/65/16，$820 225/55/17，$850 235/55/17，$980 235/50/18，$950 255/45/18，$1080 245/45/19，$980 255/45/19，$1180 275/40/19，$1250 245/40/20，$1280 245/45/20，$1300 255/40/20，$1350 275/35/20，$1450 歐洲品牌格林輪胎 熱賣好評！德國技術，品質保證！ 多謝大家的支持‍♂️‍♂️！ 本公司繼續極力推薦使用 歐洲品牌 格林輪胎 進化科技 定義未來 高強度胎體設計,完美匹配，表現出精湛抓地力與轉向性能。 胎邊結構:雙層聚酯纖維 雙層胎邊結構設計,提供絕佳過彎支撐性能,給於胎面在彎道中保有最大摩擦面積,賦予極佳的安全性與操控性能 A級濕滑✅胎面特殊配方，直線紋路設計有效降低阻滾動噪音，提高濕地性能。 強力轉向✅胎圈特殊材料補強設計提升輪胎支撐性，同時為轉向性能提供強力保障。 ＃歐洲品牌 ＃格林輪胎 ＃Greentrac ＃舒適低噪音 ＃最大排水量 ＃高穩定性擋塊 ＃降低道路噪音 ＃超低滾動阻力 ＃燃油節省 ＃超高性能輪胎 Greentrac Quest-X UHP 超高性能輪胎 採用德國技術3D主動靜音設計！ 熱賣中 性價比高 一致讚好 持續發威 另備有多款專為私家車型號(格林輪呔) 滿足有要求的客人 歡迎各位查詢預約 ＃港澳總代理 ＃智盈實業 https://wa.me/85297840529 | H31: 正面 | I31: 期待 | J31: 廣告/促銷 | K31: 廣告 | L31: 無關 | M31: 田灣, 筲箕灣, 柴灣, 觀塘, 樂富, 深水埗, 沙田火炭, 上水, 粉嶺, 元朗, 屯門 | N31: null | O31: null | P31: null | Q31: 0 | R31: 0 | S31: 0
A32: https://www.facebook.com/groups/366950274676457/permalink/1685054832865988/ | B32: Anonymous participant | C32: 46083 | E32: 放一換一電動車quota，留言我pm你傾 | H32: 中性 | I32: 陳述 | J32: 廣告/促銷 | K32: 廣告 | L32: 間接相關 | M32: null | N32: null | O32: null | P32: null | Q32: 0 | R32: 0 | S32: 0
A33: https://www.facebook.com/groups/366950274676457/permalink/1685047799533358/ | B33: Electway | C33: 46083 | E33: # GB/T to CHAdeMO adapter | G33: https://scontent-ord5-3.xx.fbcdn.net/v/t39.30808-6/643573320_1448517500618420_3728041026410020012_n.jpg?stp=dst-jpg_p526x296_tt6&_nc_cat=100&ccb=1-7&_nc_sid=aa7b47&_nc_ohc=T5PU9cIY7xIQ7kNvwHH4F83&_nc_oc=AdonvIor2jyCajU_ZGIc94xZKezbM6lZzN-qoQEoc3iol7Gu0x_mUmXAM3Zyk7aimMY&_nc_zt=23&_nc_ht=scontent-ord5-3.xx&_nc_gid=Rft2ww9Bm913JFbqk7hngA&_nc_ss=72289&oh=00_Af76B5mANZ8Cc8P2UaI5omH9DtjIl6cptjktFr0Jb-SxdQ&oe=6A10B09C | H33: 中性 | I33: 陳述 | J33: 安裝/硬件/技術 | K33: 純分享 | L33: 直接相關 | M33: null | N33: null | O33: null | P33: CHAdeMO | Q33: 0 | R33: 0 | S33: 0
A34: https://www.facebook.com/groups/366950274676457/permalink/1684735942897877/ | B34: JoJo Bee | C34: 46082 | E34: 全新DUOSIDA 22kwh 5米充電線 Type2出讓 | H34: 中性 | I34: 陳述 | J34: 廣告/促銷 | K34: 廣告 | L34: 直接相關 | M34: null | N34: null | O34: null | P34: Type 2, 22kW | Q34: 3 | R34: 0 | S34: 0
A35: https://www.facebook.com/groups/366950274676457/permalink/1684129122958559/ | B35: Miya Yip | C35: 46082 | E35: 私人放一換一quota 車已劏 已注銷 可即簽 $25000 煩請PM | H35: 中性 | I35: 陳述 | J35: 廣告/促銷 | K35: 廣告 | L35: 直接相關 | M35: null | N35: null | O35: null | P35: null | Q35: 0 | R35: 0 | S35: 0
A36: https://www.facebook.com/groups/366950274676457/permalink/1683741336330671/ | B36: Anonymous participant | C36: 46081 | E36: 放一換一quota 可以二簽（時間彈性） 連車$38000 | H36: 中性 | I36: 陳述 | J36: 廣告/促銷 | K36: 廣告 | L36: 間接相關 | M36: null | N36: null | O36: null | P36: null | Q36: 0 | R36: 0 | S36: 0
A37: https://www.facebook.com/groups/366950274676457/permalink/1682756033095868/ | B37: Dasyvin | C37: 46080 | E37: 荃灣又多個充電站，有8支快充，免停車費 | H37: 正面 | I37: 滿意 | J37: 充電站設施/位置 | K37: 純分享 | L37: 直接相關 | M37: 荃灣 | N37: null | O37: null | P37: 快充 | Q37: 3 | R37: 1 | S37: 0
A38: https://www.facebook.com/groups/366950274676457/permalink/1682637959774342/ | B38: Amuro Lee | C38: 46080 | E38: https://unwire.hk/2026/02/27/osaka-expo-ev-bus-graveyard-evmj-president-resign/life-tech/auto/ | H38: 負面 | I38: 失望 | J38: 安裝/硬件/技術 | K38: 純分享 | L38: 間接相關 | M38: 大阪 | N38: null | O38: null | P38: null | Q38: 0 | R38: 0 | S38: 0
A39: https://www.facebook.com/groups/366950274676457/permalink/1682372743134197/ | B39: 騎師政府私家車驗車 | C39: 46080 | E39: https://www.facebook.com/share/p/1GVZDQUDXm/?mibextid=wwXIfr | H39: 中性 | I39: 陳述 | J39: 其他 | K39: 純分享 | L39: 無關 | M39: null | N39: null | O39: null | P39: null | Q39: 0 | R39: 0 | S39: 0
A40: https://www.facebook.com/groups/366950274676457/permalink/1681367443234727/ | B40: Thomson Leung | C40: 46079 | E40: 私放1換1 車已劏 文件手續齊全 歡迎報價$35000 可大刀 | H40: 中性 | I40: 陳述 | J40: 其他 | K40: 廣告 | L40: 無關 | M40: null | N40: null | O40: null | P40: null | Q40: 0 | R40: 0 | S40: 0
...

Sheet 香港電動車資訊及充電交流谷⚡️2
A1: url | B1: user_name | C1: title | D1: text | E1: time | F1: video_url_one | G1: photo_url_one | H1: emotion_basic | I1: emotion_detailed | J1: theme | K1: info_value | L1: ev_relevance | M1: Location_Mentioned | N1: EV_Model_Mentioned | O1: Competitor_Brand | P1: Charging_Type | Q1: likesCount | R1: commentsCount | S1: sharesCount
A2: https://www.facebook.com/groups/hkevcharging/permalink/3838738269754532/ | B2: Man Leung Tang | D2: 想問下係街超充,見到之槍180kw,但用時只食40kw ,係我車有問題定支槍唔得?定2樣都有影響? byd atto2 新手求教 | E2: 46159 | H2: 中性 | I2: 疑問 | J2: 充電速度 | K2: 求助 | L2: 直接相關 | M2: null | N2: BYD Atto 2 | O2: null | P2: 超充, 180kW | Q2: 6 | R2: 33 | S2: 0
A3: https://www.facebook.com/groups/hkevcharging/permalink/3840167806278245/ | B3: Simon Chan | D3: 請教下淘寶果D充電椿有邊隻介紹？ | E3: 46159 | H3: 中性 | I3: 疑問 | J3: 安裝/硬件/技術 | K3: 求助 | L3: 直接相關 | M3: null | N3: null | O3: null | P3: null | Q3: 0 | R3: 0 | S3: 0
A4: https://www.facebook.com/groups/hkevcharging/permalink/3836719756623050/ | B4: Mourinhang Chan | D4: 喺深水埗the clampton充電 超級搵笨 扣咗我錢又叉唔到電 同佢哋講佢話部機轉藍燈 係正常 係我個架車setting同條線有問題 叫佢refund話冇得回 係咪痴L線㗎？？？？ | E4: 46156 | H4: 負面 | I4: 生氣 | J4: 顧客服務/投訴 | K4: 純分享 | L4: 直接相關 | M4: 深水埗the clampton | N4: null | O4: the clampton | P4: null | Q4: 15 | R4: 7 | S4: 0
A5: https://www.facebook.com/groups/hkevcharging/permalink/3834822616812764/ | B5: RelaxingPhoenix4030 | D5: 新收車無送中充線，想問下有無推介？ 有睇過下淘寶，我見淘寶頭牌子嗰d個價錢同喺香港買好似唔爭得遠，想問下有無推介？ thx thx!!!! | E5: 46153 | H5: 中性 | I5: 疑問 | J5: 疑問/求助 | K5: 求助 | L5: 直接相關 | M5: null | N5: null | O5: null | P5: 中充 | Q5: 4 | R5: 11 | S5: 0
A6: https://www.facebook.com/groups/hkevcharging/permalink/3834781553483537/ | B6: Daniel Tsang | D6: 中充$25/15分鐘，會唔會好貴？ | E6: 46153 | G6: https://scontent-lga3-1.xx.fbcdn.net/v/t39.30808-6/694768414_10163781285722626_1755478839361862595_n.jpg?stp=dst-jpg_s720x720_tt6&_nc_cat=111&ccb=1-7&_nc_sid=aa7b47&_nc_ohc=E5cnWTQTWwAQ7kNvwFBcTeF&_nc_oc=AdqoRSCfBdmdbQdLupiVBo_5FUjAFlyZuVpUI-7aNcPsJrR-_sRlNHK1nquLwkv7LCI&_nc_zt=23&_nc_ht=scontent-lga3-1.xx&_nc_gid=3j0lBml65shZDASSRGFMrQ&_nc_ss=72289&oh=00_Af5q_bNSCtfkS-ZIESQMW4GFG5-ElujBF6E6YmWKc5D0yg&oe=6A109928 | H6: 中性 | I6: 疑問 | J6: 收費/價錢 | K6: 求助 | L6: 直接相關 | M6: null | N6: null | O6: null | P6: 中充 | Q6: 26 | R6: 48 | S6: 0
A7: https://www.facebook.com/groups/hkevcharging/permalink/3831851643776528/ | B7: Simon Lee | D7: 大角咀 One Bedford Place 停車場，終於有TESLA免費EV充電 | E7: 46150 | G7: https://scontent-lga3-3.xx.fbcdn.net/v/t39.30808-6/690754592_122181778604912952_4892225293964943803_n.jpg?stp=dst-jpg_p180x540_tt6&_nc_cat=102&ccb=1-7&_nc_sid=aa7b47&_nc_ohc=A-DemmPUU6QQ7kNvwGQzFhx&_nc_oc=AdpEwWgiIS-nuDKq0gZwaP15n9RiqLGH9ud4QzejSXvPtYzBOtKF1VibHGAuRqQAwM4&_nc_zt=23&_nc_ht=scontent-lga3-3.xx&_nc_gid=11Ag9PaxbTjF5sjYlX57lQ&_nc_ss=72289&oh=00_Af4cIiWzNQGCVloUYTfinQeG_yEWS7LK5K6EHN-FiZxPZg&oe=6A109913 | H7: 正面 | I7: 開心 | J7: 充電站設施/位置 | K7: 純分享 | L7: 直接相關 | M7: 大角咀 One Bedford Place | N7: null | O7: Tesla | P7: null | Q7: 2 | R7: 0 | S7: 0
A8: https://www.facebook.com/groups/hkevcharging/permalink/3830326100595749/ | B8: Wai Kin Lam | D8: 想問下各位師兄，最近入咗部電動車，本身租緊村屋泊樓下，係咪買條13A充電線比較好？買原廠定淘寶就得？ | E8: 46149 | H8: 中性 | I8: 疑問 | J8: 安裝/硬件/技術 | K8: 求助 | L8: 直接相關 | M8: null | N8: null | O8: null | P8: 13A | Q8: 8 | R8: 32 | S8: 0
A9: https://www.facebook.com/groups/hkevcharging/permalink/3830612397233786/ | B9: Man Leung Tang | D9: 元朗不用泊車錢充電站,請師兄們比意見 想問元朗充電邊度平同唔洗停車場錢? | E9: 46149 | H9: 中性 | I9: 疑問 | J9: 收費/價錢 | K9: 求助 | L9: 直接相關 | M9: 元朗 | N9: null | O9: null | P9: null | Q9: 0 | R9: 2 | S9: 0
A10: https://www.facebook.com/groups/hkevcharging/permalink/3826833960944963/ | B10: ExcellentCapybara4767 | D10: 請問大家屋苑停車場裝充電係裝type A 定Type B?Thanks | E10: 46146 | H10: 中性 | I10: 疑問 | J10: 安裝/硬件/技術 | K10: 求助 | L10: 直接相關 | M10: null | N10: null | O10: null | P10: null | Q10: 1 | R10: 9 | S10: 0
A11: https://www.facebook.com/groups/hkevcharging/permalink/3819746774987015/ | B11: Lisa Chun | D11: 各位師兄姐，請問如果係租屋住（可能住兩年就搬），裝咩充電樁性價比較高？ | E11: 46139 | H11: 中性 | I11: 疑問 | J11: 安裝/硬件/技術 | K11: 求助 | L11: 直接相關 | M11: null | N11: null | O11: null | P11: null | Q11: 5 | R11: 14 | S11: 0
A12: https://www.facebook.com/groups/hkevcharging/permalink/3817298091898550/ | B12: 6969everyday | D12: 請問屋苑掛充電錶有冇邊間好？同埋有咩野要注意？ | E12: 46134 | H12: 中性 | I12: 疑問 | J12: 安裝/硬件/技術 | K12: 求助 | L12: 直接相關 | M12: null | N12: null | O12: null | P12: null | Q12: 1 | R12: 3 | S12: 0
A13: https://www.facebook.com/groups/hkevcharging/permalink/3811755882452771/ | B13: Sheldon Cso | D13: 準備搬村屋，想裝掛牆充電，屋企單相電，而我自己本身有Tesla 充電樁大家有冇介紹啊或者13a三腳插，有冇邊款安全啲？ | E13: 46128 | H13: 中性 | I13: 疑問 | J13: 安裝/硬件/技術 | K13: 求助 | L13: 直接相關 | M13: null | N13: null | O13: null | P13: 13A | Q13: 1 | R13: 9 | S13: 0
A14: https://www.facebook.com/groups/hkevcharging/permalink/3809003552728004/ | B14: Yat Him Li | D14: 想問下大家，第一次換電車，村屋裝充電器，有冇公司/師傅推介？Maxus mifa7，唔該 | E14: 46125 | H14: 中性 | I14: 疑問 | J14: 安裝/硬件/技術 | K14: 求助 | L14: 直接相關 | M14: null | N14: Maxus Mifa 7 | O14: null | P14: null | Q14: 2 | R14: 5 | S14: 0
A15: https://www.facebook.com/groups/hkevcharging/permalink/3809407896020903/ | B15: Kelvin Kwan | D15: 各位師兄師姐，想請教大家，小弟剛換電車，剛申請港車北上，想問問國內歐標轉國標邊款快充安全又穩陣，可否給我品牌意見 | E15: 46125 | H15: 中性 | I15: 疑問 | J15: 疑問/求助 | K15: 求助 | L15: 直接相關 | M15: null | N15: null | O15: null | P15: 快充 | Q15: 2 | R15: 17 | S15: 0
A16: https://www.facebook.com/groups/hkevcharging/permalink/3807290412899318/ | B16: BIG ECHO 大迴音國際有限公司 | D16: 岩岩去左偉業街間充電加洗車，兩樣都平又唔洗充值次次八達通清。洗車100，充電百幾kw $2.5 | E16: 46123 | H16: 正面 | I16: 滿意 | J16: 收費/價錢 | K16: 純分享 | L16: 直接相關 | M16: 偉業街 | N16: null | O16: null | P16: 快充 | Q16: 61 | R16: 23 | S16: 4
A17: https://www.facebook.com/groups/hkevcharging/permalink/3806245859670440/ | B17: Ka Ka Chan | D17: Cornerstone 6折充電私放 有意請PM | E17: 46121 | H17: 正面 | I17: 期待 | J17: 廣告/促銷 | K17: 廣告 | L17: 間接相關 | M17: null | N17: null | O17: Cornerstone | P17: null | Q17: 3 | R17: 2 | S17: 0
A18: https://www.facebook.com/groups/hkevcharging/permalink/3801129613515398/ | B18: Kilowatt 充電入油地圖 - 香港駕車資訊平台 | D18: **【一換一結束】2026年3月電動車首次登記9,000輛創新高！BYD比亞迪超1,700輛‼️** 一換一結束最後機會下，3月一共登記咗超過 9,000部 電動私家車，創歷史單月新高！BYD比亞迪超1,700輛；其後是Tesla超1,650輛。最受歡迎電動車是BYD ATTO 2 有近1,500輛；其後是Tesla Model Y 1,000輛 。 電動車銷量排名頭五位： 1️⃣ BYD ATTO 2 - 1497 輛 2️⃣ Tesla Model Y - 989 輛 3️⃣ DFSK Nammi VIGO - 844輛 4️⃣ ZEEKR 7X – 732輛 5️⃣ Tesla Model 3 – 686輛 *以運輸署登記數字為準 想知邊款電動車最好賣？ 即下載 Kilowatt App 睇詳細數據 [kilowatt.hk/download](http://kilowatt.hk/download) | E18: 46115 | H18: 中性 | I18: 陳述 | J18: 資訊分享 | K18: 廣告 | L18: 直接相關 | M18: null | N18: BYD ATTO 2, Tesla Model Y, DFSK Nammi VIGO, ZEEKR 7X, Tesla Model 3 | O18: Kilowatt | P18: null | Q18: 3 | R18: 0 | S18: 0
A19: https://www.facebook.com/groups/hkevcharging/permalink/3794213707540322/ | B19: Leon Lee | D19: 想請教一下大家 又kWh / kw充電點計?入電入到幾多? 電池容量83kwh , 800v平台, 功率80kw 謝謝 | E19: 46108 | H19: 中性 | I19: 疑問 | J19: 疑問/求助 | K19: 求助 | L19: 直接相關 | M19: null | N19: null | O19: null | P19: 80kW, 800V | Q19: 14 | R19: 36 | S19: 0
A20: https://www.facebook.com/groups/hkevcharging/permalink/3792852127676480/ | B20: Hongkonger852 | D20: 康城商場，麻煩車主見到請盡快移走！ | E20: 46107 | G20: https://scontent-iad3-2.xx.fbcdn.net/v/t39.30808-6/658404380_1612343260097066_3105031426292490265_n.jpg?stp=dst-jpg_p526x296_tt6&_nc_cat=111&ccb=1-7&_nc_sid=aa7b47&_nc_ohc=-38ifBI-dhQQ7kNvwFpeom0&_nc_oc=AdoB4Z8GRHGBmBWkzgywLHShvQH9Xa73DgsPiThJ2xpoN2CMd5bnWcus9AJA0Ux21FM&_nc_zt=23&_nc_ht=scontent-iad3-2.xx&_nc_gid=wHWi3smkAzLjRG6GFjJwoA&_nc_ss=7c289&oh=00_Af6w2nOfOVyr_jM-XwpraaiE1wUL-qZbvvN8I6gkFZLTvw&oe=6A10B387 | H20: 負面 | I20: 生氣 | J20: 排隊/打尖/霸位 | K20: 純分享 | L20: 直接相關 | M20: 康城商場 | N20: null | O20: null | P20: null | Q20: 34 | R20: 41 | S20: 0
A21: https://www.facebook.com/groups/hkevcharging/permalink/3792170717744621/ | B21: Yang Sunny | D21: 各位師兄，有無平靚正維修特斯拉溫度控製糸統（無冷氣，加左雪種又漏曬)的廠房介紹？原廠太貴了 | E21: 46106 | H21: 中性 | I21: 疑問 | J21: 疑問/求助 | K21: 求助 | L21: 無關 | M21: null | N21: Tesla | O21: null | P21: null | Q21: 0 | R21: 2 | S21: 0
A22: https://www.facebook.com/groups/hkevcharging/permalink/3789772817984411/ | B22: Sophia Wong | E22: 46103 | Q22: 1 | R22: 0 | S22: 0
A23: https://www.facebook.com/groups/hkevcharging/permalink/3787336534894706/ | B23: MK Hei | D23: 改版SU7 22萬人仔，可以返珠海買返架玩吓￼ | E23: 46100 | G23: https://scontent-mia3-1.xx.fbcdn.net/v/t39.30808-6/654296295_10164069748667748_6641903258806315416_n.jpg?stp=dst-jpg_s565x565_tt6&_nc_cat=106&ccb=1-7&_nc_sid=aa7b47&_nc_ohc=mb8Lvt-pXLEQ7kNvwFZ4xRr&_nc_oc=AdqiT2s8zOF0JEODJ-9tpT0rEpl6Mk7kiKUU49L3YQ5rWHk2WRkffUB16-AVQpbFFeU&_nc_zt=23&_nc_ht=scontent-mia3-1.xx&_nc_gid=BrW9EJNMrZz3Uq5qCE4NxQ&_nc_ss=72289&oh=00_Af799xhfzMGi4lK0vUCmSB2INryqdUiBzGN__EFyqpUdAQ&oe=6A10C604 | H23: 中性 | I23: 陳述 | J23: 資訊分享 | K23: 有行動意向 | L23: 直接相關 | M23: 珠海 | N23: SU7 | O23: null | P23: null | Q23: 63 | R23: 29 | S23: 0
A24: https://www.facebook.com/groups/hkevcharging/permalink/3782775732017453/ | B24: Chan Po Man | D24: #ev 全新平治VLE 系列（廣東話翻譯介紹）Mercedes-Benz VLE Electric MPV 全面取代EQV系列 內部配置全面升級｜續航力達700公里｜#vle #eqv #benz https://youtu.be/SfIOvQe_O38 | E24: 46095 | G24: https://scontent-iad3-1.xx.fbcdn.net/v/t39.30808-6/651678700_1613101989998604_2508606350972551329_n.jpg?stp=dst-jpg_s960x960_tt6&_nc_cat=110&ccb=1-7&_nc_sid=aa7b47&_nc_ohc=ObQLW5ojfpQQ7kNvwFJA_-Z&_nc_oc=Ado2wkBYasFwxqJXgoKNy3AbL7sKtQ4qFbkt-1hvzImKRz6e_KDnExCOAQiCl8TdC-k&_nc_zt=23&_nc_ht=scontent-iad3-1.xx&_nc_gid=7aHhyHut_VSUKuW2xgasVg&_nc_ss=72289&oh=00_Af5F5xYJa_0Xud4akWbedGFXA024BR1ghXfD5ntp4PsBXQ&oe=6A10AFBF | H24: 正面 | I24: 期待 | J24: 廣告/促銷 | K24: 廣告 | L24: 間接相關 | M24: null | N24: Mercedes-Benz VLE, Mercedes-Benz EQV | O24: null | P24: null | Q24: 0 | R24: 0 | S24: 0
A25: https://www.facebook.com/groups/hkevcharging/permalink/3781772132117813/ | B25: Wai So | D25: 新用比亚比迪海獅7普通版，一星期用三天車左右，家裏装了獨立13A單相電掣，問問各師兄師姊有甚麼13A充電線好介紹？ | E25: 46094 | H25: 中性 | I25: 疑問 | J25: 疑問/求助 | K25: 求助 | L25: 直接相關 | M25: null | N25: 比亞迪海獅7 | O25: null | P25: 13A | Q25: 2 | R25: 17 | S25: 0
A26: https://www.facebook.com/groups/hkevcharging/permalink/3780866132208413/ | B26: Rebecca Lam | D26: 家用汽車叉电机，請問大家有無推介? | E26: 46093 | H26: 中性 | I26: 疑問 | J26: 疑問/求助 | K26: 求助 | L26: 直接相關 | M26: null | N26: null | O26: null | P26: null | Q26: 0 | R26: 3 | S26: 0
A27: https://www.facebook.com/groups/hkevcharging/permalink/3775221122772914/ | B27: MK Hei | D27: ￼一月暫時Zeekr 7X排第一，嚟緊睇吓三月一換一deadline邊個排第一先 | E27: 46086 | G27: https://scontent-ord5-2.xx.fbcdn.net/v/t39.30808-6/646136323_10163994273737748_3263070594301087378_n.jpg?stp=cp6_dst-jpg_p526x296_tt6&_nc_cat=104&ccb=1-7&_nc_sid=aa7b47&_nc_ohc=lecjNyDk_SYQ7kNvwHrXws2&_nc_oc=Adqv18fCv9Au_BIz1GNGHQ4qmItsgzJnrVIBe3veS5HIKmk2B2fRiiiL5vnXTannMoI&_nc_zt=23&_nc_ht=scontent-ord5-2.xx&_nc_gid=inwYP-ZINVkb3BPfq3NmOg&_nc_ss=7d289&oh=00_Af5Jhpi-w09z-qvEJVIN62R74427PzJoPs4AYlfsgCgTiA&oe=6A109C58 | H27: 中性 | I27: 陳述 | J27: 資訊分享 | K27: 純分享 | L27: 間接相關 | M27: null | N27: Zeekr 7X | O27: null | P27: null | Q27: 155 | R27: 31 | S27: 1
A28: https://www.facebook.com/groups/hkevcharging/permalink/3771795243115502/ | B28: Tsui Yu Ting | D28: 邊隻牌子嘅叉電機 比較易用 | E28: 46082 | H28: 中性 | I28: 疑問 | J28: 疑問/求助 | K28: 求助 | L28: 直接相關 | M28: null | N28: null | O28: null | P28: null | Q28: 0 | R28: 2 | S28: 0
A29: https://www.facebook.com/groups/hkevcharging/permalink/3769151960046497/ | B29: Victor Fung | D29: 請問Tesla Model Y 港車北上，中／快充轉換頭那款穩陣？ 淘寶的可以嗎？ | E29: 46080 | H29: 中性 | I29: 疑問 | J29: 疑問/求助 | K29: 求助 | L29: 直接相關 | M29: null | N29: Tesla Model Y | O29: null | P29: 中充/快充轉換頭 | Q29: 2 | R29: 9 | S29: 0
A30: https://www.facebook.com/groups/hkevcharging/permalink/3768334086794951/ | B30: Kwok Frankie | D30: 有無Brother 裝了A1w既充電器.comment如何.Thx | E30: 46078 | G30: https://scontent.fagc1-1.fna.fbcdn.net/v/t39.30808-6/642710550_25194664206874330_8166633197619759916_n.jpg?stp=dst-jpg_p526x296_tt6&_nc_cat=101&ccb=1-7&_nc_sid=aa7b47&_nc_ohc=7tXoKrFtv1AQ7kNvwGhHzju&_nc_oc=AdojbQ0Q5FNZ7NDizYpdZ6SZ0egzRqRqU7FFIASU8vifDcjjaZt69c2H6YXviKsm0XJP0F7lUxzyeC6Adi-Gb-Lh&_nc_zt=23&_nc_ht=scontent.fagc1-1.fna&_nc_gid=qGdLuqZxiF0hjhF2jHFUjg&_nc_ss=72289&oh=00_Af7XXxDeMbbXBU6r-SaS3cDOPgH1Z07-_Z8nnVBIxFpkRw&oe=6A10AE9D | H30: 中性 | I30: 疑問 | J30: 疑問/求助 | K30: 求助 | L30: 直接相關 | M30: null | N30: null | O30: null | P30: A1w | Q30: 0 | R30: 0 | S30: 0
A31: https://www.facebook.com/groups/hkevcharging/permalink/3753938491567844/ | B31: CopperPeapod2800 | D31: 60kw得24 kw | E31: 46078 | H31: 負面 | I31: 失望 | J31: 充電速度 | K31: 純分享 | L31: 直接相關 | M31: null | N31: null | O31: null | P31: 60kW, 24kW | Q31: 9 | R31: 7 | S31: 0
A32: https://www.facebook.com/groups/hkevcharging/permalink/3755099904785036/ | B32: Cheng Chris CC | D32: 經過見到火炭工業區充電站 $10度電？！係咪真架 | E32: 46078 | G32: https://scontent-dfw6-1.xx.fbcdn.net/v/t39.30808-6/629436437_793057113823225_58077082496708103_n.jpg?stp=dst-jpg_s720x720_tt6&_nc_cat=101&ccb=1-7&_nc_sid=aa7b47&_nc_ohc=Z8PzkEzOqRsQ7kNvwG_ueu2&_nc_oc=AdoiVGuw1NY6vT-8pWPjQ9JaYfIGLRNsSaA36ZTV6bepBUopPBvpXHeOnl2u2MU3sL0&_nc_zt=23&_nc_ht=scontent-dfw6-1.xx&_nc_gid=Ox6QFjUEige0dERYcTu9Aw&_nc_ss=72289&oh=00_Af4_YomIRoX1q43bidCGYhqQqZt6yrbF4fgjs9ydyA1USg&oe=6A10AAB9 | H32: 中性 | I32: 疑問 | J32: 收費/價錢 | K32: 求助 | L32: 直接相關 | M32: 火炭工業區 | N32: null | O32: null | P32: null | Q32: 29 | R32: 11 | S32: 0
A33: https://www.facebook.com/groups/hkevcharging/permalink/3752841158344244/ | B33: Sammy Ng | D33: 最近換電車，但屋苑車場冇充電位，想問下各位大圍/沙田有冇唔駛收泊車費的充電設施？ 預1個月充2次左右 | E33: 46062 | H33: 中性 | I33: 疑問 | J33: 充電站設施/位置 | K33: 求助 | L33: 直接相關 | M33: 大圍, 沙田 | N33: null | O33: null | P33: null | Q33: 23 | R33: 46 | S33: 0
A34: https://www.facebook.com/groups/hkevcharging/permalink/3742447299383630/ | B34: Well Done Charge | D34: 觀塘鴻圖道6-8號 設有10枝高達250kWh 車充，開張期$2.2/Kw 不用按金可八達通付款 | E34: 46051 | H34: 中性 | I34: 陳述 | J34: 收費/價錢 | K34: 廣告 | L34: 直接相關 | M34: 觀塘 | N34: null | O34: null | P34: 250kW | Q34: 61 | R34: 17 | S34: 0
A35: https://www.facebook.com/groups/hkevcharging/permalink/3741543679473992/ | B35: KC Wong | D35: 北角消防局對面車場，叉電45分中有叉電券送 | E35: 46051 | H35: 中性 | I35: 陳述 | J35: 資訊分享 | K35: 純分享 | L35: 直接相關 | M35: 北角 | N35: null | O35: null | P35: null | Q35: 3 | R35: 0 | S35: 2
A36: https://www.facebook.com/groups/hkevcharging/permalink/3734565240171836/ | B36: Tere Wong | D36: 請問各位師美孚附近嘅充電有無抵用好介紹呢 THX | E36: 46043 | H36: 中性 | I36: 疑問 | J36: 疑問/求助 | K36: 求助 | L36: 直接相關 | M36: 美孚 | N36: null | O36: null | P36: null | Q36: 2 | R36: 8 | S36: 1
